Workbook

Sheet LEIA-ME
A1: O Beco Gelato — dados para ficha técnica e tabela nutricional
A2: Revisão de 21/10/2026
A4: O que tem aqui | B4: Sete sabores de linha, todos zero lactose. Uma aba por sabor, mais a aba INSUMOS com a ficha de cada ingrediente e a aba RESUMO com o comparativo.
A5: ATENÇÃO — selo de açúcar | B5: Cinco dos sete sabores sustentam 'sem adição de açúcares' com zero absoluto. DOIS NÃO: Sorbet Morango (0,470 g/100 g, vindos da Pasta Fragola a 10 g/kg, que é 47% açúcar adicionado) e Alfajor (0,010 g/100 g, vindos do biscoito). A alegação exige zero sem tolerância. Coluna 'Aç. adic.' na aba RESUMO.
A6: As fórmulas são vivas | B6: As abas de sabor calculam a composição puxando da aba INSUMOS com PROCV. Se você corrigir um valor na INSUMOS, todos os sabores que usam aquele insumo se atualizam sozinhos.
A8: ORIGEM DOS DADOS | B8: Os valores nutricionais vêm do cadastro interno do Beco, montado a partir de fichas técnicas e rótulos ao longo do tempo. NÃO substituem o rótulo físico da embalagem em uso. A coluna CONFERIR na aba INSUMOS marca onde essa verificação é mais crítica.
A10: Calda | B10: A mistura líquida pasteurizada, antes da batedeira. Todas as formulações estão por 1 kg de calda.
A11: Gelato | B11: A calda depois de batida, com ar incorporado. É o que vai no pote.
A12: Pote | B12: 140 g de produto. Com pote e tampa (10 g), 150 g na balança. Exceção: o Alfajor tem 135 g de gelato mais 15 g de biscoito por cima, fechando 150 g.
A13: Açúcares totais | B13: No sentido da ANVISA: NÃO incluem polióis. O cadastro guarda um segundo valor, 'técnico', que soma açúcar e poliol — serve para calcular doçura e ponto de congelamento, não para rótulo. As duas colunas estão separadas.
A14: Carboidratos totais | B14: NÃO calculados aqui, de propósito. A convenção de incluir ou não fibras e polióis é decisão sua. Cada componente medido está separado e os sólidos totais fecham a conta.
A15: Overrun | B15: O ar incorporado na batedeira. O cadastro usa 21% para todos; medição de 16/10 deu de 14% a 47% conforme o sabor. Não altera a composição por 100 g, altera o peso do pote cheio.
A17: Contato | B17: Gabriel Sampaio — O Beco Gelato LTDA — CNPJ 66.901.942/0001-59

Sheet INSUMOS
A1: Ficha nutricional dos insumos — valores por 100 g
A2: Editar aqui atualiza todas as abas de sabor automaticamente.
A4: Insumo | B4: Nome de rótulo | C4: Alergênicos | D4: kcal | E4: Açúcares téc. | F4: % açúcar adicionado | G4: Gorduras | H4: Gord. saturadas | I4: Gord. trans | J4: Proteínas | K4: Fibras | L4: Sólidos totais | M4: Sódio (mg) | N4: R$/kg | O4: CONFERIR
A5: AGUA | B5: água | C5: — | D5: 0 | E5: 0 | F5: 0 | G5: 0 | H5: 0 | I5: 0 | J5: 0 | K5: 0 | L5: 0 | M5: 0 | N5: 0 | O5: sem preço no cadastro
A6: BASE MEC PROTEIN | B6: base proteica | C6: LEITE | D6: 336 | E6: 19 | F6: 0 | G6: 12.5 | H6: 9 | I6: 0.8 | J6: 30 | K6: 14 | L6: 97 | M6: 340 | N6: 148.2 | O6: ingrediente COMPOSTO — pedir a lista interna ao fabricante
A7: BISCOITO ALFAJOR DE CHOCOLATE (ZERO LACTOSE) | B7: biscoito de alfajor de chocolate | C7: LEITE, GLÚTEN | D7: 437 | E7: 1.5 | F7: 0.1 | G7: 28 | H7: 21 | I7: 0.2 | J7: 4.6 | K7: 3.9 | L7: 83.6 | M7: 207 | N7: 38.46 | O7: ingrediente COMPOSTO — pedir a lista interna ao fabricante
A8: CACAU 22/24 | B8: cacau em pó alcalinizado | C8: — | D8: 340 | E8: 0 | F8: 0 | G8: 23 | H8: 14.5 | I8: 0 | J8: 0 | K8: 27.5 | L8: 100 | M8: 16.5 | N8: 130
A9: CREME DE LEITE FRESCO 35% ZL (VERDE CAMPO LACFREE) | B9: creme de leite zero lactose | C9: LEITE | D9: 335 | E9: 2.7 | F9: 0 | G9: 35 | H9: 24 | I9: 0 | J9: 2.4 | K9: 0 | L9: 41 | M9: 79 | N9: 57.8
A10: CREMOBENE PREMIUM (LIGA NEUTRA) | B10: — | C10: — | D10: 670 | E10: 0 | F10: 0 | G10: 68 | H10: 0 | I10: 0 | J10: 1 | K10: 25 | L10: 94 | M10: 0 | N10: 105.84 | O10: sem nome de rótulo definido
A11: DELÍCIA DE AMENDOIM PROTEICO | B11: creme de amendoim proteico | C11: AMENDOIM, LEITE | D11: 591 | E11: 6.8 | F11: 0 | G11: 49 | H11: 6.8 | I11: 0 | J11: 17 | K11: 2.1 | L11: 97 | M11: 76 | N11: 94.25
A12: DOCE DE LEITE VIÇOSA ZERO | B12: — | C12: — | D12: 188 | E12: 33 | F12: 0 | G12: 7.2 | H12: 1.6 | I12: 0 | J12: 8.4 | K12: 0.6 | L12: 65 | M12: 188 | N12: 99.75 | O12: sem nome de rótulo definido
A13: ERITRITOL | B13: eritritol | C13: — | D13: 20 | E13: 100 | F13: 0 | G13: 0 | H13: 0 | I13: 0 | J13: 0 | K13: 0 | L13: 100 | M13: 0 | N13: 53.76
A14: GLICEROL (GLICERINA BIDESTILADA) | B14: umectante glicerol | C14: — | D14: 400 | E14: 100 | F14: 0 | G14: 0 | H14: 0 | I14: 0 | J14: 0 | K14: 0 | L14: 100 | M14: 0 | N14: 24
A15: GUSTO LIMONE SICILIA (PÓ) | B15: preparado de limão siciliano | C15: — | D15: 436 | E15: 33 | F15: 0 | G15: 1 | H15: 0.5 | I15: 0 | J15: 0.5 | K15: 1 | L15: 97 | M15: 50 | N15: 359.62
A16: LEITE EM PO DESNATADO ZL (BATAVO PENSE ZERO) | B16: — | C16: — | D16: 350 | E16: 50 | F16: 0 | G16: 1 | H16: 0.5 | I16: 0 | J16: 35 | K16: 0 | L16: 96 | M16: 385 | N16: 65.7 | O16: sem nome de rótulo definido
A17: LEITE ZERO LACTOSE (INTEGRAL) | B17: leite integral zero lactose | C17: LEITE | D17: 66 | E17: 4.6 | F17: 0 | G17: 4 | H17: 2.7 | I17: 0 | J17: 3.5 | K17: 0 | L17: 12.6 | M17: 62 | N17: 9.8
A18: MALTITOL | B18: maltitol | C18: — | D18: 240 | E18: 99 | F18: 0 | G18: 0 | H18: 0 | I18: 0 | J18: 0 | K18: 0 | L18: 99 | M18: 0 | N18: 37.78
A19: MANGA | B19: polpa de manga | C19: — | D19: 60 | E19: 14 | F19: 0 | G19: 0.3 | H19: 0 | I19: 0 | J19: 1 | K19: 1.5 | L19: 17 | M19: 2 | N19: 22
A20: MARACUJA (POLPA) | B20: polpa de maracujá | C20: — | D20: 68 | E20: 14 | F20: 0 | G20: 0.3 | H20: 0 | I20: 0 | J20: 1 | K20: 1.5 | L20: 16 | M20: 2 | N20: 30
A21: MIX OFICIAL | B21: — | C21: — | D21: 122.092 | E21: 41.944 | F21: 0 | G21: 0 | H21: 0 | I21: 0 | J21: 0.324 | K21: 54.622 | L21: 96.89 | M21: 11 | N21: 49.134 | O21: sem nome de rótulo definido; feito na casa — ver composição na seção do Mix Oficial
A22: MORANGO | B22: polpa de morango | C22: — | D22: 32 | E22: 5 | F22: 0 | G22: 0.3 | H22: 0 | I22: 0 | J22: 1 | K22: 2 | L22: 9 | M22: 2 | N22: 11.29
A23: PASTA CAFÉ SELECTA (BALDE 2 KG) | B23: pasta de café | C23: — | D23: 210 | E23: 40 | F23: 0 | G23: 0.5 | H23: 0.2 | I23: 0 | J23: 0.5 | K23: 0.5 | L23: 56 | M23: 50 | N23: 90
A24: PASTA FRAGOLA MEC3 (18047) | B24: pasta de morango | C24: — | D24: 262.4 | E24: 49.7 | F24: 47 | G24: 0.1 | H24: 0 | I24: 0 | J24: 0.2 | K24: 0 | L24: 70 | M24: 24 | N24: 142.27
A25: PASTA PISTACCHIO 100% CALIFÓRNIA | B25: pasta de pistache | C25: PISTACHE | D25: 591 | E25: 5.7 | F25: 0 | G25: 48 | H25: 12 | I25: 0 | J25: 29 | K25: 9 | L25: 96 | M25: 0 | N25: 450
A26: POLIDEXTROSE | B26: polidextrose | C26: — | D26: 100 | E26: 5 | F26: 0 | G26: 0 | H26: 0 | I26: 0 | J26: 0 | K26: 90 | L26: 95 | M26: 20 | N26: 28.92
A27: SAL | B27: sal | C27: — | D27: 0 | E27: 0 | F27: 0 | G27: 0 | H27: 0 | I27: 0 | J27: 0 | K27: 0 | L27: 98.7 | M27: 38758 | N27: 3
A28: STEVIA | B28: edulcorante glicosídeos de esteviol | C28: — | D28: 0 | E28: 100 | F28: 0 | G28: 0 | H28: 0 | I28: 0 | J28: 0 | K28: 0 | L28: 100 | M28: 0 | N28: 3100

Sheet COMPOSTOS
A1: Ingredientes preparados na casa
A2: Precisam aparecer desdobrados nos componentes na lista de ingredientes do rótulo.
A4: MIX OFICIAL — usado no Pistache e na Torta de Limão
A5: Componente | B5: partes | C5: % do total | D5: Por 1 kg
A6: POLIDEXTROSE | B6: 528 | C6: =B6/SUM(B$6:B$10) | D6: =C6*1000
A7: MALTITOL | B7: 224 | C7: =B7/SUM(B$6:B$10) | D7: =C7*1000
A8: ERITRITOL | B8: 163 | C8: =B8/SUM(B$6:B$10) | D8: =C8*1000
A9: INULINA | B9: 81 | C9: =B9/SUM(B$6:B$10) | D9: =C9*1000
A10: STEVIA | B10: 3 | C10: =B10/SUM(B$6:B$10) | D10: =C10*1000
A11: TOTAL | B11: =SUM(B6:B10) | D11: 1000
A14: BASE PROTEICA — usada no Café e no Brigadeiro
A15: Componente | B15: g por kg de base | C15: % do total | D15: Por 1 kg
A16: LEITE ZERO LACTOSE (INTEGRAL) | B16: 692.4 | C16: =B16/SUM(B$16:B$23) | D16: =C16*1000
A17: BASE MEC PROTEIN | B17: 130 | C17: =B17/SUM(B$16:B$23) | D17: =C17*1000
A18: LEITE EM PO DESNATADO ZL (BATAVO PENSE ZERO) | B18: 120 | C18: =B18/SUM(B$16:B$23) | D18: =C18*1000
A19: GLICEROL (GLICERINA BIDESTILADA) | B19: 30 | C19: =B19/SUM(B$16:B$23) | D19: =C19*1000
A20: POLIDEXTROSE | B20: 20 | C20: =B20/SUM(B$16:B$23) | D20: =C20*1000
A21: CREMOBENE PREMIUM (LIGA NEUTRA) | B21: 3.1 | C21: =B21/SUM(B$16:B$23) | D21: =C21*1000
A22: SAL | B22: 1 | C22: =B22/SUM(B$16:B$23) | D22: =C22*1000
A23: STEVIA | B23: 0.6 | C23: =B23/SUM(B$16:B$23) | D23: =C23*1000
A24: TOTAL | B24: =SUM(B16:B23) | D24: 1000
A27: Saborização da base proteica
A28: Sabor | B28: Base por kg de calda | C28: Saborizante | D28: g/kg | E28: Proteína final
A29: Café Proteico | B29: 943.2 | C29: Pasta Café Selecta | D29: 56.8 | E29: 9,99%
A30: Brigadeiro Proteico | B30: 961.5 | C30: Cacau 22/24 | D30: 38.5 | E30: 10,13%

Sheet Café Proteico
A1: Café Proteico
A2: linha BOOST · família de formulação: proteica · pote de 140 g
A4: Ingrediente | B4: Nome de rótulo | C4: g por kg de calda | D4: % da calda | E4: g no pote | F4: kcal | G4: Açúc. téc. | H4: Aç. adic. | I4: Gord. | J4: G.sat. | K4: G.trans | L4: Prot. | M4: Fibra | N4: Sól.tot. | O4: Sódio mg
A5: LEITE ZERO LACTOSE (INTEGRAL) | B5: leite integral zero lactose | C5: 655 | D5: =C5/SUM(C$5:C$13) | E5: 82.242 | F5: =IFERROR(VLOOKUP($A5,INSUMOS!$A$5:$N$28,4,FALSE),0)*$E5/100 | G5: =IFERROR(VLOOKUP($A5,INSUMOS!$A$5:$N$28,5,FALSE),0)*$E5/100 | H5: =IFERROR(VLOOKUP($A5,INSUMOS!$A$5:$N$28,6,FALSE),0)*$E5/100/100 | I5: =IFERROR(VLOOKUP($A5,INSUMOS!$A$5:$N$28,7,FALSE),0)*$E5/100 | J5: =IFERROR(VLOOKUP($A5,INSUMOS!$A$5:$N$28,8,FALSE),0)*$E5/100 | K5: =IFERROR(VLOOKUP($A5,INSUMOS!$A$5:$N$28,9,FALSE),0)*$E5/100 | L5: =IFERROR(VLOOKUP($A5,INSUMOS!$A$5:$N$28,10,FALSE),0)*$E5/100 | M5: =IFERROR(VLOOKUP($A5,INSUMOS!$A$5:$N$28,11,FALSE),0)*$E5/100 | N5: =IFERROR(VLOOKUP($A5,INSUMOS!$A$5:$N$28,12,FALSE),0)*$E5/100 | O5: =IFERROR(VLOOKUP($A5,INSUMOS!$A$5:$N$28,13,FALSE),0)*$E5/100
A6: BASE MEC PROTEIN | B6: base proteica | C6: 123 | D6: =C6/SUM(C$5:C$13) | E6: 15.444 | F6: =IFERROR(VLOOKUP($A6,INSUMOS!$A$5:$N$28,4,FALSE),0)*$E6/100 | G6: =IFERROR(VLOOKUP($A6,INSUMOS!$A$5:$N$28,5,FALSE),0)*$E6/100 | H6: =IFERROR(VLOOKUP($A6,INSUMOS!$A$5:$N$28,6,FALSE),0)*$E6/100/100 | I6: =IFERROR(VLOOKUP($A6,INSUMOS!$A$5:$N$28,7,FALSE),0)*$E6/100 | J6: =IFERROR(VLOOKUP($A6,INSUMOS!$A$5:$N$28,8,FALSE),0)*$E6/100 | K6: =IFERROR(VLOOKUP($A6,INSUMOS!$A$5:$N$28,9,FALSE),0)*$E6/100 | L6: =IFERROR(VLOOKUP($A6,INSUMOS!$A$5:$N$28,10,FALSE),0)*$E6/100 | M6: =IFERROR(VLOOKUP($A6,INSUMOS!$A$5:$N$28,11,FALSE),0)*$E6/100 | N6: =IFERROR(VLOOKUP($A6,INSUMOS!$A$5:$N$28,12,FALSE),0)*$E6/100 | O6: =IFERROR(VLOOKUP($A6,INSUMOS!$A$5:$N$28,13,FALSE),0)*$E6/100
A7: LEITE EM PO DESNATADO ZL (BATAVO PENSE ZERO) | B7: leite em po desnatado zl (batavo pense zero) | C7: 113.5 | D7: =C7/SUM(C$5:C$13) | E7: 14.251 | F7: =IFERROR(VLOOKUP($A7,INSUMOS!$A$5:$N$28,4,FALSE),0)*$E7/100 | G7: =IFERROR(VLOOKUP($A7,INSUMOS!$A$5:$N$28,5,FALSE),0)*$E7/100 | H7: =IFERROR(VLOOKUP($A7,INSUMOS!$A$5:$N$28,6,FALSE),0)*$E7/100/100 | I7: =IFERROR(VLOOKUP($A7,INSUMOS!$A$5:$N$28,7,FALSE),0)*$E7/100 | J7: =IFERROR(VLOOKUP($A7,INSUMOS!$A$5:$N$28,8,FALSE),0)*$E7/100 | K7: =IFERROR(VLOOKUP($A7,INSUMOS!$A$5:$N$28,9,FALSE),0)*$E7/100 | L7: =IFERROR(VLOOKUP($A7,INSUMOS!$A$5:$N$28,10,FALSE),0)*$E7/100 | M7: =IFERROR(VLOOKUP($A7,INSUMOS!$A$5:$N$28,11,FALSE),0)*$E7/100 | N7: =IFERROR(VLOOKUP($A7,INSUMOS!$A$5:$N$28,12,FALSE),0)*$E7/100 | O7: =IFERROR(VLOOKUP($A7,INSUMOS!$A$5:$N$28,13,FALSE),0)*$E7/100
A8: PASTA CAFÉ SELECTA (BALDE 2 KG) | B8: pasta de café | C8: 56.8 | D8: =C8/SUM(C$5:C$13) | E8: 7.132 | F8: =IFERROR(VLOOKUP($A8,INSUMOS!$A$5:$N$28,4,FALSE),0)*$E8/100 | G8: =IFERROR(VLOOKUP($A8,INSUMOS!$A$5:$N$28,5,FALSE),0)*$E8/100 | H8: =IFERROR(VLOOKUP($A8,INSUMOS!$A$5:$N$28,6,FALSE),0)*$E8/100/100 | I8: =IFERROR(VLOOKUP($A8,INSUMOS!$A$5:$N$28,7,FALSE),0)*$E8/100 | J8: =IFERROR(VLOOKUP($A8,INSUMOS!$A$5:$N$28,8,FALSE),0)*$E8/100 | K8: =IFERROR(VLOOKUP($A8,INSUMOS!$A$5:$N$28,9,FALSE),0)*$E8/100 | L8: =IFERROR(VLOOKUP($A8,INSUMOS!$A$5:$N$28,10,FALSE),0)*$E8/100 | M8: =IFERROR(VLOOKUP($A8,INSUMOS!$A$5:$N$28,11,FALSE),0)*$E8/100 | N8: =IFERROR(VLOOKUP($A8,INSUMOS!$A$5:$N$28,12,FALSE),0)*$E8/100 | O8: =IFERROR(VLOOKUP($A8,INSUMOS!$A$5:$N$28,13,FALSE),0)*$E8/100
A9: GLICEROL (GLICERINA BIDESTILADA) | B9: umectante glicerol | C9: 28.4 | D9: =C9/SUM(C$5:C$13) | E9: 3.566 | F9: =IFERROR(VLOOKUP($A9,INSUMOS!$A$5:$N$28,4,FALSE),0)*$E9/100 | G9: =IFERROR(VLOOKUP($A9,INSUMOS!$A$5:$N$28,5,FALSE),0)*$E9/100 | H9: =IFERROR(VLOOKUP($A9,INSUMOS!$A$5:$N$28,6,FALSE),0)*$E9/100/100 | I9: =IFERROR(VLOOKUP($A9,INSUMOS!$A$5:$N$28,7,FALSE),0)*$E9/100 | J9: =IFERROR(VLOOKUP($A9,INSUMOS!$A$5:$N$28,8,FALSE),0)*$E9/100 | K9: =IFERROR(VLOOKUP($A9,INSUMOS!$A$5:$N$28,9,FALSE),0)*$E9/100 | L9: =IFERROR(VLOOKUP($A9,INSUMOS!$A$5:$N$28,10,FALSE),0)*$E9/100 | M9: =IFERROR(VLOOKUP($A9,INSUMOS!$A$5:$N$28,11,FALSE),0)*$E9/100 | N9: =IFERROR(VLOOKUP($A9,INSUMOS!$A$5:$N$28,12,FALSE),0)*$E9/100 | O9: =IFERROR(VLOOKUP($A9,INSUMOS!$A$5:$N$28,13,FALSE),0)*$E9/100
A10: POLIDEXTROSE | B10: polidextrose | C10: 18.9 | D10: =C10/SUM(C$5:C$13) | E10: 2.373 | F10: =IFERROR(VLOOKUP($A10,INSUMOS!$A$5:$N$28,4,FALSE),0)*$E10/100 | G10: =IFERROR(VLOOKUP($A10,INSUMOS!$A$5:$N$28,5,FALSE),0)*$E10/100 | H10: =IFERROR(VLOOKUP($A10,INSUMOS!$A$5:$N$28,6,FALSE),0)*$E10/100/100 | I10: =IFERROR(VLOOKUP($A10,INSUMOS!$A$5:$N$28,7,FALSE),0)*$E10/100 | J10: =IFERROR(VLOOKUP($A10,INSUMOS!$A$5:$N$28,8,FALSE),0)*$E10/100 | K10: =IFERROR(VLOOKUP($A10,INSUMOS!$A$5:$N$28,9,FALSE),0)*$E10/100 | L10: =IFERROR(VLOOKUP($A10,INSUMOS!$A$5:$N$28,10,FALSE),0)*$E10/100 | M10: =IFERROR(VLOOKUP($A10,INSUMOS!$A$5:$N$28,11,FALSE),0)*$E10/100 | N10: =IFERROR(VLOOKUP($A10,INSUMOS!$A$5:$N$28,12,FALSE),0)*$E10/100 | O10: =IFERROR(VLOOKUP($A10,INSUMOS!$A$5:$N$28,13,FALSE),0)*$E10/100
A11: CREMOBENE PREMIUM (LIGA NEUTRA) | B11: cremobene premium (liga neutra) | C11: 2.9 | D11: =C11/SUM(C$5:C$13) | E11: 0.364 | F11: =IFERROR(VLOOKUP($A11,INSUMOS!$A$5:$N$28,4,FALSE),0)*$E11/100 | G11: =IFERROR(VLOOKUP($A11,INSUMOS!$A$5:$N$28,5,FALSE),0)*$E11/100 | H11: =IFERROR(VLOOKUP($A11,INSUMOS!$A$5:$N$28,6,FALSE),0)*$E11/100/100 | I11: =IFERROR(VLOOKUP($A11,INSUMOS!$A$5:$N$28,7,FALSE),0)*$E11/100 | J11: =IFERROR(VLOOKUP($A11,INSUMOS!$A$5:$N$28,8,FALSE),0)*$E11/100 | K11: =IFERROR(VLOOKUP($A11,INSUMOS!$A$5:$N$28,9,FALSE),0)*$E11/100 | L11: =IFERROR(VLOOKUP($A11,INSUMOS!$A$5:$N$28,10,FALSE),0)*$E11/100 | M11: =IFERROR(VLOOKUP($A11,INSUMOS!$A$5:$N$28,11,FALSE),0)*$E11/100 | N11: =IFERROR(VLOOKUP($A11,INSUMOS!$A$5:$N$28,12,FALSE),0)*$E11/100 | O11: =IFERROR(VLOOKUP($A11,INSUMOS!$A$5:$N$28,13,FALSE),0)*$E11/100
A12: SAL | B12: sal | C12: 0.9 | D12: =C12/SUM(C$5:C$13) | E12: 0.113 | F12: =IFERROR(VLOOKUP($A12,INSUMOS!$A$5:$N$28,4,FALSE),0)*$E12/100 | G12: =IFERROR(VLOOKUP($A12,INSUMOS!$A$5:$N$28,5,FALSE),0)*$E12/100 | H12: =IFERROR(VLOOKUP($A12,INSUMOS!$A$5:$N$28,6,FALSE),0)*$E12/100/100 | I12: =IFERROR(VLOOKUP($A12,INSUMOS!$A$5:$N$28,7,FALSE),0)*$E12/100 | J12: =IFERROR(VLOOKUP($A12,INSUMOS!$A$5:$N$28,8,FALSE),0)*$E12/100 | K12: =IFERROR(VLOOKUP($A12,INSUMOS!$A$5:$N$28,9,FALSE),0)*$E12/100 | L12: =IFERROR(VLOOKUP($A12,INSUMOS!$A$5:$N$28,10,FALSE),0)*$E12/100 | M12: =IFERROR(VLOOKUP($A12,INSUMOS!$A$5:$N$28,11,FALSE),0)*$E12/100 | N12: =IFERROR(VLOOKUP($A12,INSUMOS!$A$5:$N$28,12,FALSE),0)*$E12/100 | O12: =IFERROR(VLOOKUP($A12,INSUMOS!$A$5:$N$28,13,FALSE),0)*$E12/100
A13: STEVIA | B13: edulcorante glicosídeos de esteviol | C13: 0.6 | D13: =C13/SUM(C$5:C$13) | E13: 0.075 | F13: =IFERROR(VLOOKUP($A13,INSUMOS!$A$5:$N$28,4,FALSE),0)*$E13/100 | G13: =IFERROR(VLOOKUP($A13,INSUMOS!$A$5:$N$28,5,FALSE),0)*$E13/100 | H13: =IFERROR(VLOOKUP($A13,INSUMOS!$A$5:$N$28,6,FALSE),0)*$E13/100/100 | I13: =IFERROR(VLOOKUP($A13,INSUMOS!$A$5:$N$28,7,FALSE),0)*$E13/100 | J13: =IFERROR(VLOOKUP($A13,INSUMOS!$A$5:$N$28,8,FALSE),0)*$E13/100 | K13: =IFERROR(VLOOKUP($A13,INSUMOS!$A$5:$N$28,9,FALSE),0)*$E13/100 | L13: =IFERROR(VLOOKUP($A13,INSUMOS!$A$5:$N$28,10,FALSE),0)*$E13/100 | M13: =IFERROR(VLOOKUP($A13,INSUMOS!$A$5:$N$28,11,FALSE),0)*$E13/100 | N13: =IFERROR(VLOOKUP($A13,INSUMOS!$A$5:$N$28,12,FALSE),0)*$E13/100 | O13: =IFERROR(VLOOKUP($A13,INSUMOS!$A$5:$N$28,13,FALSE),0)*$E13/100
A14: DELÍCIA DE AMENDOIM PROTEICO | B14: creme de amendoim proteico | C14: 115 | D14: =C14/SUM(C$5:C$13) | E14: 14.439 | F14: =IFERROR(VLOOKUP($A14,INSUMOS!$A$5:$N$28,4,FALSE),0)*$E14/100 | G14: =IFERROR(VLOOKUP($A14,INSUMOS!$A$5:$N$28,5,FALSE),0)*$E14/100 | H14: =IFERROR(VLOOKUP($A14,INSUMOS!$A$5:$N$28,6,FALSE),0)*$E14/100/100 | I14: =IFERROR(VLOOKUP($A14,INSUMOS!$A$5:$N$28,7,FALSE),0)*$E14/100 | J14: =IFERROR(VLOOKUP($A14,INSUMOS!$A$5:$N$28,8,FALSE),0)*$E14/100 | K14: =IFERROR(VLOOKUP($A14,INSUMOS!$A$5:$N$28,9,FALSE),0)*$E14/100 | L14: =IFERROR(VLOOKUP($A14,INSUMOS!$A$5:$N$28,10,FALSE),0)*$E14/100 | M14: =IFERROR(VLOOKUP($A14,INSUMOS!$A$5:$N$28,11,FALSE),0)*$E14/100 | N14: =IFERROR(VLOOKUP($A14,INSUMOS!$A$5:$N$28,12,FALSE),0)*$E14/100 | O14: =IFERROR(VLOOKUP($A14,INSUMOS!$A$5:$N$28,13,FALSE),0)*$E14/100
A15: TOTAL NO POTE | C15: =SUM(C5:C13) | E15: =SUM(E5:E14) | F15: =SUM(F5:F14) | G15: =SUM(G5:G14) | H15: =SUM(H5:H14) | I15: =SUM(I5:I14) | J15: =SUM(J5:J14) | K15: =SUM(K5:K14) | L15: =SUM(L5:L14) | ... O15: =SUM(O5:O14)
A17: POR 100 g DE PRODUTO
A18: Componente | B18: Valor | C18: Unidade
A19: Valor energético | B19: =F15/140*100 | C19: kcal
A20: Açúcares totais (rótulo) | B20: 15.313 | C20: g
A21: dos quais adicionados | B21: =H15/140*100 | C21: g
A22: Polióis | B22: 0 | C22: g
A23: Fibras alimentares | B23: =M15/140*100 | C23: g
A24: Proteínas | B24: =L15/140*100 | C24: g
A25: Gorduras totais | B25: =I15/140*100 | C25: g
A26: das quais saturadas | B26: =J15/140*100 | C26: g
A27: das quais trans | B27: =K15/140*100 | C27: g
A28: Sódio | B28: =O15/140*100 | C28: mg
A29: Sólidos totais | B29: =N15/140*100 | C29: g
A30: Açúcares técnicos (uso interno) | B30: 15.313 | C30: g
A32: PARÂMETROS DA CALDA
A33: Sólidos totais | B33: 39.32 | C33: %
A34: Água | B34: 60.68 | C34: %
A35: Gordura | B35: 4.5 | C35: %
A36: Proteína | B36: 9.99 | C36: %
A37: POD | B37: 180.37
A38: PAC | B38: 353.73
A39: Janela de consumo | B39: -15.1 a -19.8 | C39: °C
A40: Água congelada a −8 °C | B40: 60.37 | C40: %
A42: LISTA DE INGREDIENTES — RDC 727/2022
A43: Ingredientes: leite integral zero lactose, base proteica, creme de amendoim proteico, leite em po desnatado zl (batavo pense zero), pasta de café, umectante glicerol, polidextrose, cremobene premium (liga neutra), sal, edulcorante glicosídeos de esteviol.
A44: ALÉRGICOS: CONTÉM LEITE, AMENDOIM.
...

Sheet Pistache
A1: Pistache
A2: linha SPECIAL · família de formulação: proteica · pote de 140 g
A4: Ingrediente | B4: Nome de rótulo | C4: g por kg de calda | D4: % da calda | E4: g no pote | F4: kcal | G4: Açúc. téc. | H4: Aç. adic. | I4: Gord. | J4: G.sat. | K4: G.trans | L4: Prot. | M4: Fibra | N4: Sól.tot. | O4: Sódio mg
A5: LEITE ZERO LACTOSE (INTEGRAL) | B5: leite integral zero lactose | C5: 654.8 | D5: =C5/SUM(C$5:C$12) | E5: 91.672 | F5: =IFERROR(VLOOKUP($A5,INSUMOS!$A$5:$N$28,4,FALSE),0)*$E5/100 | G5: =IFERROR(VLOOKUP($A5,INSUMOS!$A$5:$N$28,5,FALSE),0)*$E5/100 | H5: =IFERROR(VLOOKUP($A5,INSUMOS!$A$5:$N$28,6,FALSE),0)*$E5/100/100 | I5: =IFERROR(VLOOKUP($A5,INSUMOS!$A$5:$N$28,7,FALSE),0)*$E5/100 | J5: =IFERROR(VLOOKUP($A5,INSUMOS!$A$5:$N$28,8,FALSE),0)*$E5/100 | K5: =IFERROR(VLOOKUP($A5,INSUMOS!$A$5:$N$28,9,FALSE),0)*$E5/100 | L5: =IFERROR(VLOOKUP($A5,INSUMOS!$A$5:$N$28,10,FALSE),0)*$E5/100 | M5: =IFERROR(VLOOKUP($A5,INSUMOS!$A$5:$N$28,11,FALSE),0)*$E5/100 | N5: =IFERROR(VLOOKUP($A5,INSUMOS!$A$5:$N$28,12,FALSE),0)*$E5/100 | O5: =IFERROR(VLOOKUP($A5,INSUMOS!$A$5:$N$28,13,FALSE),0)*$E5/100
A6: MIX OFICIAL | B6: mix oficial | C6: 120 | D6: =C6/SUM(C$5:C$12) | E6: 16.8 | F6: =IFERROR(VLOOKUP($A6,INSUMOS!$A$5:$N$28,4,FALSE),0)*$E6/100 | G6: =IFERROR(VLOOKUP($A6,INSUMOS!$A$5:$N$28,5,FALSE),0)*$E6/100 | H6: =IFERROR(VLOOKUP($A6,INSUMOS!$A$5:$N$28,6,FALSE),0)*$E6/100/100 | I6: =IFERROR(VLOOKUP($A6,INSUMOS!$A$5:$N$28,7,FALSE),0)*$E6/100 | J6: =IFERROR(VLOOKUP($A6,INSUMOS!$A$5:$N$28,8,FALSE),0)*$E6/100 | K6: =IFERROR(VLOOKUP($A6,INSUMOS!$A$5:$N$28,9,FALSE),0)*$E6/100 | L6: =IFERROR(VLOOKUP($A6,INSUMOS!$A$5:$N$28,10,FALSE),0)*$E6/100 | M6: =IFERROR(VLOOKUP($A6,INSUMOS!$A$5:$N$28,11,FALSE),0)*$E6/100 | N6: =IFERROR(VLOOKUP($A6,INSUMOS!$A$5:$N$28,12,FALSE),0)*$E6/100 | O6: =IFERROR(VLOOKUP($A6,INSUMOS!$A$5:$N$28,13,FALSE),0)*$E6/100
A7: PASTA PISTACCHIO 100% CALIFÓRNIA | B7: pasta de pistache | C7: 90 | D7: =C7/SUM(C$5:C$12) | E7: 12.6 | F7: =IFERROR(VLOOKUP($A7,INSUMOS!$A$5:$N$28,4,FALSE),0)*$E7/100 | G7: =IFERROR(VLOOKUP($A7,INSUMOS!$A$5:$N$28,5,FALSE),0)*$E7/100 | H7: =IFERROR(VLOOKUP($A7,INSUMOS!$A$5:$N$28,6,FALSE),0)*$E7/100/100 | I7: =IFERROR(VLOOKUP($A7,INSUMOS!$A$5:$N$28,7,FALSE),0)*$E7/100 | J7: =IFERROR(VLOOKUP($A7,INSUMOS!$A$5:$N$28,8,FALSE),0)*$E7/100 | K7: =IFERROR(VLOOKUP($A7,INSUMOS!$A$5:$N$28,9,FALSE),0)*$E7/100 | L7: =IFERROR(VLOOKUP($A7,INSUMOS!$A$5:$N$28,10,FALSE),0)*$E7/100 | M7: =IFERROR(VLOOKUP($A7,INSUMOS!$A$5:$N$28,11,FALSE),0)*$E7/100 | N7: =IFERROR(VLOOKUP($A7,INSUMOS!$A$5:$N$28,12,FALSE),0)*$E7/100 | O7: =IFERROR(VLOOKUP($A7,INSUMOS!$A$5:$N$28,13,FALSE),0)*$E7/100
A8: CREME DE LEITE FRESCO 35% ZL (VERDE CAMPO LACFREE) | B8: creme de leite zero lactose | C8: 62 | D8: =C8/SUM(C$5:C$12) | E8: 8.68 | F8: =IFERROR(VLOOKUP($A8,INSUMOS!$A$5:$N$28,4,FALSE),0)*$E8/100 | G8: =IFERROR(VLOOKUP($A8,INSUMOS!$A$5:$N$28,5,FALSE),0)*$E8/100 | H8: =IFERROR(VLOOKUP($A8,INSUMOS!$A$5:$N$28,6,FALSE),0)*$E8/100/100 | I8: =IFERROR(VLOOKUP($A8,INSUMOS!$A$5:$N$28,7,FALSE),0)*$E8/100 | J8: =IFERROR(VLOOKUP($A8,INSUMOS!$A$5:$N$28,8,FALSE),0)*$E8/100 | K8: =IFERROR(VLOOKUP($A8,INSUMOS!$A$5:$N$28,9,FALSE),0)*$E8/100 | L8: =IFERROR(VLOOKUP($A8,INSUMOS!$A$5:$N$28,10,FALSE),0)*$E8/100 | M8: =IFERROR(VLOOKUP($A8,INSUMOS!$A$5:$N$28,11,FALSE),0)*$E8/100 | N8: =IFERROR(VLOOKUP($A8,INSUMOS!$A$5:$N$28,12,FALSE),0)*$E8/100 | O8: =IFERROR(VLOOKUP($A8,INSUMOS!$A$5:$N$28,13,FALSE),0)*$E8/100
A9: LEITE EM PO DESNATADO ZL (BATAVO PENSE ZERO) | B9: leite em po desnatado zl (batavo pense zero) | C9: 33 | D9: =C9/SUM(C$5:C$12) | E9: 4.62 | F9: =IFERROR(VLOOKUP($A9,INSUMOS!$A$5:$N$28,4,FALSE),0)*$E9/100 | G9: =IFERROR(VLOOKUP($A9,INSUMOS!$A$5:$N$28,5,FALSE),0)*$E9/100 | H9: =IFERROR(VLOOKUP($A9,INSUMOS!$A$5:$N$28,6,FALSE),0)*$E9/100/100 | I9: =IFERROR(VLOOKUP($A9,INSUMOS!$A$5:$N$28,7,FALSE),0)*$E9/100 | J9: =IFERROR(VLOOKUP($A9,INSUMOS!$A$5:$N$28,8,FALSE),0)*$E9/100 | K9: =IFERROR(VLOOKUP($A9,INSUMOS!$A$5:$N$28,9,FALSE),0)*$E9/100 | L9: =IFERROR(VLOOKUP($A9,INSUMOS!$A$5:$N$28,10,FALSE),0)*$E9/100 | M9: =IFERROR(VLOOKUP($A9,INSUMOS!$A$5:$N$28,11,FALSE),0)*$E9/100 | N9: =IFERROR(VLOOKUP($A9,INSUMOS!$A$5:$N$28,12,FALSE),0)*$E9/100 | O9: =IFERROR(VLOOKUP($A9,INSUMOS!$A$5:$N$28,13,FALSE),0)*$E9/100
A10: ERITRITOL | B10: eritritol | C10: 20 | D10: =C10/SUM(C$5:C$12) | E10: 2.8 | F10: =IFERROR(VLOOKUP($A10,INSUMOS!$A$5:$N$28,4,FALSE),0)*$E10/100 | G10: =IFERROR(VLOOKUP($A10,INSUMOS!$A$5:$N$28,5,FALSE),0)*$E10/100 | H10: =IFERROR(VLOOKUP($A10,INSUMOS!$A$5:$N$28,6,FALSE),0)*$E10/100/100 | I10: =IFERROR(VLOOKUP($A10,INSUMOS!$A$5:$N$28,7,FALSE),0)*$E10/100 | J10: =IFERROR(VLOOKUP($A10,INSUMOS!$A$5:$N$28,8,FALSE),0)*$E10/100 | K10: =IFERROR(VLOOKUP($A10,INSUMOS!$A$5:$N$28,9,FALSE),0)*$E10/100 | L10: =IFERROR(VLOOKUP($A10,INSUMOS!$A$5:$N$28,10,FALSE),0)*$E10/100 | M10: =IFERROR(VLOOKUP($A10,INSUMOS!$A$5:$N$28,11,FALSE),0)*$E10/100 | N10: =IFERROR(VLOOKUP($A10,INSUMOS!$A$5:$N$28,12,FALSE),0)*$E10/100 | O10: =IFERROR(VLOOKUP($A10,INSUMOS!$A$5:$N$28,13,FALSE),0)*$E10/100
A11: GLICEROL (GLICERINA BIDESTILADA) | B11: umectante glicerol | C11: 15 | D11: =C11/SUM(C$5:C$12) | E11: 2.1 | F11: =IFERROR(VLOOKUP($A11,INSUMOS!$A$5:$N$28,4,FALSE),0)*$E11/100 | G11: =IFERROR(VLOOKUP($A11,INSUMOS!$A$5:$N$28,5,FALSE),0)*$E11/100 | H11: =IFERROR(VLOOKUP($A11,INSUMOS!$A$5:$N$28,6,FALSE),0)*$E11/100/100 | I11: =IFERROR(VLOOKUP($A11,INSUMOS!$A$5:$N$28,7,FALSE),0)*$E11/100 | J11: =IFERROR(VLOOKUP($A11,INSUMOS!$A$5:$N$28,8,FALSE),0)*$E11/100 | K11: =IFERROR(VLOOKUP($A11,INSUMOS!$A$5:$N$28,9,FALSE),0)*$E11/100 | L11: =IFERROR(VLOOKUP($A11,INSUMOS!$A$5:$N$28,10,FALSE),0)*$E11/100 | M11: =IFERROR(VLOOKUP($A11,INSUMOS!$A$5:$N$28,11,FALSE),0)*$E11/100 | N11: =IFERROR(VLOOKUP($A11,INSUMOS!$A$5:$N$28,12,FALSE),0)*$E11/100 | O11: =IFERROR(VLOOKUP($A11,INSUMOS!$A$5:$N$28,13,FALSE),0)*$E11/100
A12: CREMOBENE PREMIUM (LIGA NEUTRA) | B12: cremobene premium (liga neutra) | C12: 5.2 | D12: =C12/SUM(C$5:C$12) | E12: 0.728 | F12: =IFERROR(VLOOKUP($A12,INSUMOS!$A$5:$N$28,4,FALSE),0)*$E12/100 | G12: =IFERROR(VLOOKUP($A12,INSUMOS!$A$5:$N$28,5,FALSE),0)*$E12/100 | H12: =IFERROR(VLOOKUP($A12,INSUMOS!$A$5:$N$28,6,FALSE),0)*$E12/100/100 | I12: =IFERROR(VLOOKUP($A12,INSUMOS!$A$5:$N$28,7,FALSE),0)*$E12/100 | J12: =IFERROR(VLOOKUP($A12,INSUMOS!$A$5:$N$28,8,FALSE),0)*$E12/100 | K12: =IFERROR(VLOOKUP($A12,INSUMOS!$A$5:$N$28,9,FALSE),0)*$E12/100 | L12: =IFERROR(VLOOKUP($A12,INSUMOS!$A$5:$N$28,10,FALSE),0)*$E12/100 | M12: =IFERROR(VLOOKUP($A12,INSUMOS!$A$5:$N$28,11,FALSE),0)*$E12/100 | N12: =IFERROR(VLOOKUP($A12,INSUMOS!$A$5:$N$28,12,FALSE),0)*$E12/100 | O12: =IFERROR(VLOOKUP($A12,INSUMOS!$A$5:$N$28,13,FALSE),0)*$E12/100
A13: TOTAL NO POTE | C13: =SUM(C5:C12) | E13: =SUM(E5:E12) | F13: =SUM(F5:F12) | G13: =SUM(G5:G12) | H13: =SUM(H5:H12) | I13: =SUM(I5:I12) | J13: =SUM(J5:J12) | K13: =SUM(K5:K12) | L13: =SUM(L5:L12) | ... O13: =SUM(O5:O12)
A15: POR 100 g DE PRODUTO
A16: Componente | B16: Valor | C16: Unidade
A17: Valor energético | B17: =F13/140*100 | C17: kcal
A18: Açúcares totais (rótulo) | B18: 7.254 | C18: g
A19: dos quais adicionados | B19: =H13/140*100 | C19: g
A20: Polióis | B20: 6.622 | C20: g
A21: Fibras alimentares | B21: =M13/140*100 | C21: g
A22: Proteínas | B22: =L13/140*100 | C22: g
A23: Gorduras totais | B23: =I13/140*100 | C23: g
A24: das quais saturadas | B24: =J13/140*100 | C24: g
A25: das quais trans | B25: =K13/140*100 | C25: g
A26: Sódio | B26: =O13/140*100 | C26: mg
A27: Sólidos totais | B27: =N13/140*100 | C27: g
A28: Açúcares técnicos (uso interno) | B28: 13.876 | C28: g
A30: PARÂMETROS DA CALDA
A31: Sólidos totais | B31: 38.22 | C31: %
A32: Água | B32: 61.78 | C32: %
A33: Gordura | B33: 9.5 | C33: %
A34: Proteína | B34: 6.25 | C34: %
A35: POD | B35: 148.02
A36: PAC | B36: 330.15
A37: Janela de consumo | B37: -13.8 a -18.2 | C37: °C
A38: Água congelada a −8 °C | B38: 63.67 | C38: %
A40: LISTA DE INGREDIENTES — RDC 727/2022
A41: Ingredientes: leite integral zero lactose, pasta de pistache, polidextrose, creme de leite zero lactose, eritritol, leite em po desnatado zl (batavo pense zero), maltitol, umectante glicerol, inulina, cremobene premium (liga neutra), edulcorante glicosídeos de esteviol.
A42: ALÉRGICOS: CONTÉM LEITE, PISTACHE.
A43: Selos: ALTO TEOR DE FIBRAS · FONTE DE PROTEÍNA · SEM ADIÇÃO DE AÇÚCARES
A44: Lupa frontal: nenhuma

Sheet Manga com Maracujá
A1: Manga com Maracujá
A2: linha FRESH · família de formulação: fruta / agua · pote de 140 g
A4: Ingrediente | B4: Nome de rótulo | C4: g por kg de calda | D4: % da calda | E4: g no pote | F4: kcal | G4: Açúc. téc. | H4: Aç. adic. | I4: Gord. | J4: G.sat. | K4: G.trans | L4: Prot. | M4: Fibra | N4: Sól.tot. | O4: Sódio mg
A5: MANGA | B5: polpa de manga | C5: 479 | D5: =C5/SUM(C$5:C$11) | E5: 67.06 | F5: =IFERROR(VLOOKUP($A5,INSUMOS!$A$5:$N$28,4,FALSE),0)*$E5/100 | G5: =IFERROR(VLOOKUP($A5,INSUMOS!$A$5:$N$28,5,FALSE),0)*$E5/100 | H5: =IFERROR(VLOOKUP($A5,INSUMOS!$A$5:$N$28,6,FALSE),0)*$E5/100/100 | I5: =IFERROR(VLOOKUP($A5,INSUMOS!$A$5:$N$28,7,FALSE),0)*$E5/100 | J5: =IFERROR(VLOOKUP($A5,INSUMOS!$A$5:$N$28,8,FALSE),0)*$E5/100 | K5: =IFERROR(VLOOKUP($A5,INSUMOS!$A$5:$N$28,9,FALSE),0)*$E5/100 | L5: =IFERROR(VLOOKUP($A5,INSUMOS!$A$5:$N$28,10,FALSE),0)*$E5/100 | M5: =IFERROR(VLOOKUP($A5,INSUMOS!$A$5:$N$28,11,FALSE),0)*$E5/100 | N5: =IFERROR(VLOOKUP($A5,INSUMOS!$A$5:$N$28,12,FALSE),0)*$E5/100 | O5: =IFERROR(VLOOKUP($A5,INSUMOS!$A$5:$N$28,13,FALSE),0)*$E5/100
A6: MARACUJA (POLPA) | B6: polpa de maracujá | C6: 235 | D6: =C6/SUM(C$5:C$11) | E6: 32.9 | F6: =IFERROR(VLOOKUP($A6,INSUMOS!$A$5:$N$28,4,FALSE),0)*$E6/100 | G6: =IFERROR(VLOOKUP($A6,INSUMOS!$A$5:$N$28,5,FALSE),0)*$E6/100 | H6: =IFERROR(VLOOKUP($A6,INSUMOS!$A$5:$N$28,6,FALSE),0)*$E6/100/100 | I6: =IFERROR(VLOOKUP($A6,INSUMOS!$A$5:$N$28,7,FALSE),0)*$E6/100 | J6: =IFERROR(VLOOKUP($A6,INSUMOS!$A$5:$N$28,8,FALSE),0)*$E6/100 | K6: =IFERROR(VLOOKUP($A6,INSUMOS!$A$5:$N$28,9,FALSE),0)*$E6/100 | L6: =IFERROR(VLOOKUP($A6,INSUMOS!$A$5:$N$28,10,FALSE),0)*$E6/100 | M6: =IFERROR(VLOOKUP($A6,INSUMOS!$A$5:$N$28,11,FALSE),0)*$E6/100 | N6: =IFERROR(VLOOKUP($A6,INSUMOS!$A$5:$N$28,12,FALSE),0)*$E6/100 | O6: =IFERROR(VLOOKUP($A6,INSUMOS!$A$5:$N$28,13,FALSE),0)*$E6/100
A7: MIX OFICIAL | B7: mix oficial | C7: 120 | D7: =C7/SUM(C$5:C$11) | E7: 16.8 | F7: =IFERROR(VLOOKUP($A7,INSUMOS!$A$5:$N$28,4,FALSE),0)*$E7/100 | G7: =IFERROR(VLOOKUP($A7,INSUMOS!$A$5:$N$28,5,FALSE),0)*$E7/100 | H7: =IFERROR(VLOOKUP($A7,INSUMOS!$A$5:$N$28,6,FALSE),0)*$E7/100/100 | I7: =IFERROR(VLOOKUP($A7,INSUMOS!$A$5:$N$28,7,FALSE),0)*$E7/100 | J7: =IFERROR(VLOOKUP($A7,INSUMOS!$A$5:$N$28,8,FALSE),0)*$E7/100 | K7: =IFERROR(VLOOKUP($A7,INSUMOS!$A$5:$N$28,9,FALSE),0)*$E7/100 | L7: =IFERROR(VLOOKUP($A7,INSUMOS!$A$5:$N$28,10,FALSE),0)*$E7/100 | M7: =IFERROR(VLOOKUP($A7,INSUMOS!$A$5:$N$28,11,FALSE),0)*$E7/100 | N7: =IFERROR(VLOOKUP($A7,INSUMOS!$A$5:$N$28,12,FALSE),0)*$E7/100 | O7: =IFERROR(VLOOKUP($A7,INSUMOS!$A$5:$N$28,13,FALSE),0)*$E7/100
A8: AGUA | B8: água | C8: 78 | D8: =C8/SUM(C$5:C$11) | E8: 10.92 | F8: =IFERROR(VLOOKUP($A8,INSUMOS!$A$5:$N$28,4,FALSE),0)*$E8/100 | G8: =IFERROR(VLOOKUP($A8,INSUMOS!$A$5:$N$28,5,FALSE),0)*$E8/100 | H8: =IFERROR(VLOOKUP($A8,INSUMOS!$A$5:$N$28,6,FALSE),0)*$E8/100/100 | I8: =IFERROR(VLOOKUP($A8,INSUMOS!$A$5:$N$28,7,FALSE),0)*$E8/100 | J8: =IFERROR(VLOOKUP($A8,INSUMOS!$A$5:$N$28,8,FALSE),0)*$E8/100 | K8: =IFERROR(VLOOKUP($A8,INSUMOS!$A$5:$N$28,9,FALSE),0)*$E8/100 | L8: =IFERROR(VLOOKUP($A8,INSUMOS!$A$5:$N$28,10,FALSE),0)*$E8/100 | M8: =IFERROR(VLOOKUP($A8,INSUMOS!$A$5:$N$28,11,FALSE),0)*$E8/100 | N8: =IFERROR(VLOOKUP($A8,INSUMOS!$A$5:$N$28,12,FALSE),0)*$E8/100 | O8: =IFERROR(VLOOKUP($A8,INSUMOS!$A$5:$N$28,13,FALSE),0)*$E8/100
A9: POLIDEXTROSE | B9: polidextrose | C9: 70 | D9: =C9/SUM(C$5:C$11) | E9: 9.8 | F9: =IFERROR(VLOOKUP($A9,INSUMOS!$A$5:$N$28,4,FALSE),0)*$E9/100 | G9: =IFERROR(VLOOKUP($A9,INSUMOS!$A$5:$N$28,5,FALSE),0)*$E9/100 | H9: =IFERROR(VLOOKUP($A9,INSUMOS!$A$5:$N$28,6,FALSE),0)*$E9/100/100 | I9: =IFERROR(VLOOKUP($A9,INSUMOS!$A$5:$N$28,7,FALSE),0)*$E9/100 | J9: =IFERROR(VLOOKUP($A9,INSUMOS!$A$5:$N$28,8,FALSE),0)*$E9/100 | K9: =IFERROR(VLOOKUP($A9,INSUMOS!$A$5:$N$28,9,FALSE),0)*$E9/100 | L9: =IFERROR(VLOOKUP($A9,INSUMOS!$A$5:$N$28,10,FALSE),0)*$E9/100 | M9: =IFERROR(VLOOKUP($A9,INSUMOS!$A$5:$N$28,11,FALSE),0)*$E9/100 | N9: =IFERROR(VLOOKUP($A9,INSUMOS!$A$5:$N$28,12,FALSE),0)*$E9/100 | O9: =IFERROR(VLOOKUP($A9,INSUMOS!$A$5:$N$28,13,FALSE),0)*$E9/100
A10: GLICEROL (GLICERINA BIDESTILADA) | B10: umectante glicerol | C10: 15 | D10: =C10/SUM(C$5:C$11) | E10: 2.1 | F10: =IFERROR(VLOOKUP($A10,INSUMOS!$A$5:$N$28,4,FALSE),0)*$E10/100 | G10: =IFERROR(VLOOKUP($A10,INSUMOS!$A$5:$N$28,5,FALSE),0)*$E10/100 | H10: =IFERROR(VLOOKUP($A10,INSUMOS!$A$5:$N$28,6,FALSE),0)*$E10/100/100 | I10: =IFERROR(VLOOKUP($A10,INSUMOS!$A$5:$N$28,7,FALSE),0)*$E10/100 | J10: =IFERROR(VLOOKUP($A10,INSUMOS!$A$5:$N$28,8,FALSE),0)*$E10/100 | K10: =IFERROR(VLOOKUP($A10,INSUMOS!$A$5:$N$28,9,FALSE),0)*$E10/100 | L10: =IFERROR(VLOOKUP($A10,INSUMOS!$A$5:$N$28,10,FALSE),0)*$E10/100 | M10: =IFERROR(VLOOKUP($A10,INSUMOS!$A$5:$N$28,11,FALSE),0)*$E10/100 | N10: =IFERROR(VLOOKUP($A10,INSUMOS!$A$5:$N$28,12,FALSE),0)*$E10/100 | O10: =IFERROR(VLOOKUP($A10,INSUMOS!$A$5:$N$28,13,FALSE),0)*$E10/100
A11: CREMOBENE PREMIUM (LIGA NEUTRA) | B11: cremobene premium (liga neutra) | C11: 3 | D11: =C11/SUM(C$5:C$11) | E11: 0.42 | F11: =IFERROR(VLOOKUP($A11,INSUMOS!$A$5:$N$28,4,FALSE),0)*$E11/100 | G11: =IFERROR(VLOOKUP($A11,INSUMOS!$A$5:$N$28,5,FALSE),0)*$E11/100 | H11: =IFERROR(VLOOKUP($A11,INSUMOS!$A$5:$N$28,6,FALSE),0)*$E11/100/100 | I11: =IFERROR(VLOOKUP($A11,INSUMOS!$A$5:$N$28,7,FALSE),0)*$E11/100 | J11: =IFERROR(VLOOKUP($A11,INSUMOS!$A$5:$N$28,8,FALSE),0)*$E11/100 | K11: =IFERROR(VLOOKUP($A11,INSUMOS!$A$5:$N$28,9,FALSE),0)*$E11/100 | L11: =IFERROR(VLOOKUP($A11,INSUMOS!$A$5:$N$28,10,FALSE),0)*$E11/100 | M11: =IFERROR(VLOOKUP($A11,INSUMOS!$A$5:$N$28,11,FALSE),0)*$E11/100 | N11: =IFERROR(VLOOKUP($A11,INSUMOS!$A$5:$N$28,12,FALSE),0)*$E11/100 | O11: =IFERROR(VLOOKUP($A11,INSUMOS!$A$5:$N$28,13,FALSE),0)*$E11/100
A12: TOTAL NO POTE | C12: =SUM(C5:C11) | E12: =SUM(E5:E11) | F12: =SUM(F5:F11) | G12: =SUM(G5:G11) | H12: =SUM(H5:H11) | I12: =SUM(I5:I11) | J12: =SUM(J5:J11) | K12: =SUM(K5:K11) | L12: =SUM(L5:L11) | ... O12: =SUM(O5:O11)
A14: POR 100 g DE PRODUTO
A15: Componente | B15: Valor | C15: Unidade
A16: Valor energético | B16: =F12/140*100 | C16: kcal
A17: Açúcares totais (rótulo) | B17: 12.258 | C17: g
A18: dos quais adicionados | B18: =H12/140*100 | C18: g
A19: Polióis | B19: 4.622 | C19: g
A20: Fibras alimentares | B20: =M12/140*100 | C20: g
A21: Proteínas | B21: =L12/140*100 | C21: g
A22: Gorduras totais | B22: =I12/140*100 | C22: g
A23: das quais saturadas | B23: =J12/140*100 | C23: g
A24: das quais trans | B24: =K12/140*100 | C24: g
A25: Sódio | B25: =O12/140*100 | C25: mg
A26: Sólidos totais | B26: =N12/140*100 | C26: g
A27: Açúcares técnicos (uso interno) | B27: 16.879 | C27: g
A29: PARÂMETROS DA CALDA
A30: Sólidos totais | B30: 31.96 | C30: %
A31: Água | B31: 68.04 | C31: %
A32: Gordura | B32: 0.42 | C32: %
A33: Proteína | B33: 0.76 | C33: %
A34: POD | B34: 226.58
A35: PAC | B35: 389.19
A36: Janela de consumo | B36: -14.8 a -19.4 | C36: °C
A37: Água congelada a −8 °C | B37: 61.11 | C37: %
A39: LISTA DE INGREDIENTES — RDC 727/2022
A40: Ingredientes: polpa de manga, polpa de maracujá, polidextrose, água, maltitol, eritritol, umectante glicerol, inulina, cremobene premium (liga neutra), edulcorante glicosídeos de esteviol.
A41: Selos: ALTO TEOR DE FIBRAS · SEM ADIÇÃO DE AÇÚCARES
A42: Lupa frontal: nenhuma

Sheet Sorbet Morango
A1: Sorbet Morango
A2: linha FRESH · família de formulação: fruta / agua · pote de 140 g
A4: Ingrediente | B4: Nome de rótulo | C4: g por kg de calda | D4: % da calda | E4: g no pote | F4: kcal | G4: Açúc. téc. | H4: Aç. adic. | I4: Gord. | J4: G.sat. | K4: G.trans | L4: Prot. | M4: Fibra | N4: Sól.tot. | O4: Sódio mg
A5: MORANGO | B5: polpa de morango | C5: 629 | D5: =C5/SUM(C$5:C$11) | E5: 88.06 | F5: =IFERROR(VLOOKUP($A5,INSUMOS!$A$5:$N$28,4,FALSE),0)*$E5/100 | G5: =IFERROR(VLOOKUP($A5,INSUMOS!$A$5:$N$28,5,FALSE),0)*$E5/100 | H5: =IFERROR(VLOOKUP($A5,INSUMOS!$A$5:$N$28,6,FALSE),0)*$E5/100/100 | I5: =IFERROR(VLOOKUP($A5,INSUMOS!$A$5:$N$28,7,FALSE),0)*$E5/100 | J5: =IFERROR(VLOOKUP($A5,INSUMOS!$A$5:$N$28,8,FALSE),0)*$E5/100 | K5: =IFERROR(VLOOKUP($A5,INSUMOS!$A$5:$N$28,9,FALSE),0)*$E5/100 | L5: =IFERROR(VLOOKUP($A5,INSUMOS!$A$5:$N$28,10,FALSE),0)*$E5/100 | M5: =IFERROR(VLOOKUP($A5,INSUMOS!$A$5:$N$28,11,FALSE),0)*$E5/100 | N5: =IFERROR(VLOOKUP($A5,INSUMOS!$A$5:$N$28,12,FALSE),0)*$E5/100 | O5: =IFERROR(VLOOKUP($A5,INSUMOS!$A$5:$N$28,13,FALSE),0)*$E5/100
A6: MIX OFICIAL | B6: mix oficial | C6: 230 | D6: =C6/SUM(C$5:C$11) | E6: 32.2 | F6: =IFERROR(VLOOKUP($A6,INSUMOS!$A$5:$N$28,4,FALSE),0)*$E6/100 | G6: =IFERROR(VLOOKUP($A6,INSUMOS!$A$5:$N$28,5,FALSE),0)*$E6/100 | H6: =IFERROR(VLOOKUP($A6,INSUMOS!$A$5:$N$28,6,FALSE),0)*$E6/100/100 | I6: =IFERROR(VLOOKUP($A6,INSUMOS!$A$5:$N$28,7,FALSE),0)*$E6/100 | J6: =IFERROR(VLOOKUP($A6,INSUMOS!$A$5:$N$28,8,FALSE),0)*$E6/100 | K6: =IFERROR(VLOOKUP($A6,INSUMOS!$A$5:$N$28,9,FALSE),0)*$E6/100 | L6: =IFERROR(VLOOKUP($A6,INSUMOS!$A$5:$N$28,10,FALSE),0)*$E6/100 | M6: =IFERROR(VLOOKUP($A6,INSUMOS!$A$5:$N$28,11,FALSE),0)*$E6/100 | N6: =IFERROR(VLOOKUP($A6,INSUMOS!$A$5:$N$28,12,FALSE),0)*$E6/100 | O6: =IFERROR(VLOOKUP($A6,INSUMOS!$A$5:$N$28,13,FALSE),0)*$E6/100
A7: AGUA | B7: água | C7: 98 | D7: =C7/SUM(C$5:C$11) | E7: 13.72 | F7: =IFERROR(VLOOKUP($A7,INSUMOS!$A$5:$N$28,4,FALSE),0)*$E7/100 | G7: =IFERROR(VLOOKUP($A7,INSUMOS!$A$5:$N$28,5,FALSE),0)*$E7/100 | H7: =IFERROR(VLOOKUP($A7,INSUMOS!$A$5:$N$28,6,FALSE),0)*$E7/100/100 | I7: =IFERROR(VLOOKUP($A7,INSUMOS!$A$5:$N$28,7,FALSE),0)*$E7/100 | J7: =IFERROR(VLOOKUP($A7,INSUMOS!$A$5:$N$28,8,FALSE),0)*$E7/100 | K7: =IFERROR(VLOOKUP($A7,INSUMOS!$A$5:$N$28,9,FALSE),0)*$E7/100 | L7: =IFERROR(VLOOKUP($A7,INSUMOS!$A$5:$N$28,10,FALSE),0)*$E7/100 | M7: =IFERROR(VLOOKUP($A7,INSUMOS!$A$5:$N$28,11,FALSE),0)*$E7/100 | N7: =IFERROR(VLOOKUP($A7,INSUMOS!$A$5:$N$28,12,FALSE),0)*$E7/100 | O7: =IFERROR(VLOOKUP($A7,INSUMOS!$A$5:$N$28,13,FALSE),0)*$E7/100
A8: ERITRITOL | B8: eritritol | C8: 15 | D8: =C8/SUM(C$5:C$11) | E8: 2.1 | F8: =IFERROR(VLOOKUP($A8,INSUMOS!$A$5:$N$28,4,FALSE),0)*$E8/100 | G8: =IFERROR(VLOOKUP($A8,INSUMOS!$A$5:$N$28,5,FALSE),0)*$E8/100 | H8: =IFERROR(VLOOKUP($A8,INSUMOS!$A$5:$N$28,6,FALSE),0)*$E8/100/100 | I8: =IFERROR(VLOOKUP($A8,INSUMOS!$A$5:$N$28,7,FALSE),0)*$E8/100 | J8: =IFERROR(VLOOKUP($A8,INSUMOS!$A$5:$N$28,8,FALSE),0)*$E8/100 | K8: =IFERROR(VLOOKUP($A8,INSUMOS!$A$5:$N$28,9,FALSE),0)*$E8/100 | L8: =IFERROR(VLOOKUP($A8,INSUMOS!$A$5:$N$28,10,FALSE),0)*$E8/100 | M8: =IFERROR(VLOOKUP($A8,INSUMOS!$A$5:$N$28,11,FALSE),0)*$E8/100 | N8: =IFERROR(VLOOKUP($A8,INSUMOS!$A$5:$N$28,12,FALSE),0)*$E8/100 | O8: =IFERROR(VLOOKUP($A8,INSUMOS!$A$5:$N$28,13,FALSE),0)*$E8/100
A9: GLICEROL (GLICERINA BIDESTILADA) | B9: umectante glicerol | C9: 15 | D9: =C9/SUM(C$5:C$11) | E9: 2.1 | F9: =IFERROR(VLOOKUP($A9,INSUMOS!$A$5:$N$28,4,FALSE),0)*$E9/100 | G9: =IFERROR(VLOOKUP($A9,INSUMOS!$A$5:$N$28,5,FALSE),0)*$E9/100 | H9: =IFERROR(VLOOKUP($A9,INSUMOS!$A$5:$N$28,6,FALSE),0)*$E9/100/100 | I9: =IFERROR(VLOOKUP($A9,INSUMOS!$A$5:$N$28,7,FALSE),0)*$E9/100 | J9: =IFERROR(VLOOKUP($A9,INSUMOS!$A$5:$N$28,8,FALSE),0)*$E9/100 | K9: =IFERROR(VLOOKUP($A9,INSUMOS!$A$5:$N$28,9,FALSE),0)*$E9/100 | L9: =IFERROR(VLOOKUP($A9,INSUMOS!$A$5:$N$28,10,FALSE),0)*$E9/100 | M9: =IFERROR(VLOOKUP($A9,INSUMOS!$A$5:$N$28,11,FALSE),0)*$E9/100 | N9: =IFERROR(VLOOKUP($A9,INSUMOS!$A$5:$N$28,12,FALSE),0)*$E9/100 | O9: =IFERROR(VLOOKUP($A9,INSUMOS!$A$5:$N$28,13,FALSE),0)*$E9/100
A10: PASTA FRAGOLA MEC3 (18047) | B10: pasta de morango | C10: 10 | D10: =C10/SUM(C$5:C$11) | E10: 1.4 | F10: =IFERROR(VLOOKUP($A10,INSUMOS!$A$5:$N$28,4,FALSE),0)*$E10/100 | G10: =IFERROR(VLOOKUP($A10,INSUMOS!$A$5:$N$28,5,FALSE),0)*$E10/100 | H10: =IFERROR(VLOOKUP($A10,INSUMOS!$A$5:$N$28,6,FALSE),0)*$E10/100/100 | I10: =IFERROR(VLOOKUP($A10,INSUMOS!$A$5:$N$28,7,FALSE),0)*$E10/100 | J10: =IFERROR(VLOOKUP($A10,INSUMOS!$A$5:$N$28,8,FALSE),0)*$E10/100 | K10: =IFERROR(VLOOKUP($A10,INSUMOS!$A$5:$N$28,9,FALSE),0)*$E10/100 | L10: =IFERROR(VLOOKUP($A10,INSUMOS!$A$5:$N$28,10,FALSE),0)*$E10/100 | M10: =IFERROR(VLOOKUP($A10,INSUMOS!$A$5:$N$28,11,FALSE),0)*$E10/100 | N10: =IFERROR(VLOOKUP($A10,INSUMOS!$A$5:$N$28,12,FALSE),0)*$E10/100 | O10: =IFERROR(VLOOKUP($A10,INSUMOS!$A$5:$N$28,13,FALSE),0)*$E10/100
A11: CREMOBENE PREMIUM (LIGA NEUTRA) | B11: cremobene premium (liga neutra) | C11: 3 | D11: =C11/SUM(C$5:C$11) | E11: 0.42 | F11: =IFERROR(VLOOKUP($A11,INSUMOS!$A$5:$N$28,4,FALSE),0)*$E11/100 | G11: =IFERROR(VLOOKUP($A11,INSUMOS!$A$5:$N$28,5,FALSE),0)*$E11/100 | H11: =IFERROR(VLOOKUP($A11,INSUMOS!$A$5:$N$28,6,FALSE),0)*$E11/100/100 | I11: =IFERROR(VLOOKUP($A11,INSUMOS!$A$5:$N$28,7,FALSE),0)*$E11/100 | J11: =IFERROR(VLOOKUP($A11,INSUMOS!$A$5:$N$28,8,FALSE),0)*$E11/100 | K11: =IFERROR(VLOOKUP($A11,INSUMOS!$A$5:$N$28,9,FALSE),0)*$E11/100 | L11: =IFERROR(VLOOKUP($A11,INSUMOS!$A$5:$N$28,10,FALSE),0)*$E11/100 | M11: =IFERROR(VLOOKUP($A11,INSUMOS!$A$5:$N$28,11,FALSE),0)*$E11/100 | N11: =IFERROR(VLOOKUP($A11,INSUMOS!$A$5:$N$28,12,FALSE),0)*$E11/100 | O11: =IFERROR(VLOOKUP($A11,INSUMOS!$A$5:$N$28,13,FALSE),0)*$E11/100
A12: TOTAL NO POTE | C12: =SUM(C5:C11) | E12: =SUM(E5:E11) | F12: =SUM(F5:F11) | G12: =SUM(G5:G11) | H12: =SUM(H5:H11) | I12: =SUM(I5:I11) | J12: =SUM(J5:J11) | K12: =SUM(K5:K11) | L12: =SUM(L5:L11) | ... O12: =SUM(O5:O11)
A14: POR 100 g DE PRODUTO
A15: Componente | B15: Valor | C15: Unidade
A16: Valor energético | B16: =F12/140*100 | C16: kcal
A17: Açúcares totais (rótulo) | B17: 5.931 | C17: g
A18: dos quais adicionados | B18: =H12/140*100 | C18: g
A19: Polióis | B19: 10.358 | C19: g
A20: Fibras alimentares | B20: =M12/140*100 | C20: g
A21: Proteínas | B21: =L12/140*100 | C21: g
A22: Gorduras totais | B22: =I12/140*100 | C22: g
A23: das quais saturadas | B23: =J12/140*100 | C23: g
A24: das quais trans | B24: =K12/140*100 | C24: g
A25: Sódio | B25: =O12/140*100 | C25: mg
A26: Sólidos totais | B26: =N12/140*100 | C26: g
A27: Açúcares técnicos (uso interno) | B27: 16.289 | C27: g
A29: PARÂMETROS DA CALDA
A30: Sólidos totais | B30: 31.93 | C30: %
A31: Água | B31: 68.07 | C31: %
A32: Gordura | B32: 0.39 | C32: %
A33: Proteína | B33: 0.71 | C33: %
A34: POD | B34: 232.32
A35: PAC | B35: 388.14
A36: Janela de consumo | B36: -14.8 a -19.4 | C36: °C
A37: Água congelada a −8 °C | B37: 61.24 | C37: %
A39: LISTA DE INGREDIENTES — RDC 727/2022
A40: Ingredientes: polpa de morango, polidextrose, água, eritritol, maltitol, inulina, umectante glicerol, pasta de morango, cremobene premium (liga neutra), edulcorante glicosídeos de esteviol.
A41: Selos: ALTO TEOR DE FIBRAS
A42: Lupa frontal: nenhuma

Sheet Torta de Limão
A1: Torta de Limão
A2: linha SPECIAL · família de formulação: creme / leite · pote de 140 g
A4: Ingrediente | B4: Nome de rótulo | C4: g por kg de calda | D4: % da calda | E4: g no pote | F4: kcal | G4: Açúc. téc. | H4: Aç. adic. | I4: Gord. | J4: G.sat. | K4: G.trans | L4: Prot. | M4: Fibra | N4: Sól.tot. | O4: Sódio mg
A5: LEITE ZERO LACTOSE (INTEGRAL) | B5: leite integral zero lactose | C5: 614 | D5: =C5/SUM(C$5:C$12) | E5: 85.96 | F5: =IFERROR(VLOOKUP($A5,INSUMOS!$A$5:$N$28,4,FALSE),0)*$E5/100 | G5: =IFERROR(VLOOKUP($A5,INSUMOS!$A$5:$N$28,5,FALSE),0)*$E5/100 | H5: =IFERROR(VLOOKUP($A5,INSUMOS!$A$5:$N$28,6,FALSE),0)*$E5/100/100 | I5: =IFERROR(VLOOKUP($A5,INSUMOS!$A$5:$N$28,7,FALSE),0)*$E5/100 | J5: =IFERROR(VLOOKUP($A5,INSUMOS!$A$5:$N$28,8,FALSE),0)*$E5/100 | K5: =IFERROR(VLOOKUP($A5,INSUMOS!$A$5:$N$28,9,FALSE),0)*$E5/100 | L5: =IFERROR(VLOOKUP($A5,INSUMOS!$A$5:$N$28,10,FALSE),0)*$E5/100 | M5: =IFERROR(VLOOKUP($A5,INSUMOS!$A$5:$N$28,11,FALSE),0)*$E5/100 | N5: =IFERROR(VLOOKUP($A5,INSUMOS!$A$5:$N$28,12,FALSE),0)*$E5/100 | O5: =IFERROR(VLOOKUP($A5,INSUMOS!$A$5:$N$28,13,FALSE),0)*$E5/100
A6: MIX OFICIAL | B6: mix oficial | C6: 150 | D6: =C6/SUM(C$5:C$12) | E6: 21 | F6: =IFERROR(VLOOKUP($A6,INSUMOS!$A$5:$N$28,4,FALSE),0)*$E6/100 | G6: =IFERROR(VLOOKUP($A6,INSUMOS!$A$5:$N$28,5,FALSE),0)*$E6/100 | H6: =IFERROR(VLOOKUP($A6,INSUMOS!$A$5:$N$28,6,FALSE),0)*$E6/100/100 | I6: =IFERROR(VLOOKUP($A6,INSUMOS!$A$5:$N$28,7,FALSE),0)*$E6/100 | J6: =IFERROR(VLOOKUP($A6,INSUMOS!$A$5:$N$28,8,FALSE),0)*$E6/100 | K6: =IFERROR(VLOOKUP($A6,INSUMOS!$A$5:$N$28,9,FALSE),0)*$E6/100 | L6: =IFERROR(VLOOKUP($A6,INSUMOS!$A$5:$N$28,10,FALSE),0)*$E6/100 | M6: =IFERROR(VLOOKUP($A6,INSUMOS!$A$5:$N$28,11,FALSE),0)*$E6/100 | N6: =IFERROR(VLOOKUP($A6,INSUMOS!$A$5:$N$28,12,FALSE),0)*$E6/100 | O6: =IFERROR(VLOOKUP($A6,INSUMOS!$A$5:$N$28,13,FALSE),0)*$E6/100
A7: CREME DE LEITE FRESCO 35% ZL (VERDE CAMPO LACFREE) | B7: creme de leite zero lactose | C7: 102 | D7: =C7/SUM(C$5:C$12) | E7: 14.28 | F7: =IFERROR(VLOOKUP($A7,INSUMOS!$A$5:$N$28,4,FALSE),0)*$E7/100 | G7: =IFERROR(VLOOKUP($A7,INSUMOS!$A$5:$N$28,5,FALSE),0)*$E7/100 | H7: =IFERROR(VLOOKUP($A7,INSUMOS!$A$5:$N$28,6,FALSE),0)*$E7/100/100 | I7: =IFERROR(VLOOKUP($A7,INSUMOS!$A$5:$N$28,7,FALSE),0)*$E7/100 | J7: =IFERROR(VLOOKUP($A7,INSUMOS!$A$5:$N$28,8,FALSE),0)*$E7/100 | K7: =IFERROR(VLOOKUP($A7,INSUMOS!$A$5:$N$28,9,FALSE),0)*$E7/100 | L7: =IFERROR(VLOOKUP($A7,INSUMOS!$A$5:$N$28,10,FALSE),0)*$E7/100 | M7: =IFERROR(VLOOKUP($A7,INSUMOS!$A$5:$N$28,11,FALSE),0)*$E7/100 | N7: =IFERROR(VLOOKUP($A7,INSUMOS!$A$5:$N$28,12,FALSE),0)*$E7/100 | O7: =IFERROR(VLOOKUP($A7,INSUMOS!$A$5:$N$28,13,FALSE),0)*$E7/100
A8: GUSTO LIMONE SICILIA (PÓ) | B8: preparado de limão siciliano | C8: 60 | D8: =C8/SUM(C$5:C$12) | E8: 8.4 | F8: =IFERROR(VLOOKUP($A8,INSUMOS!$A$5:$N$28,4,FALSE),0)*$E8/100 | G8: =IFERROR(VLOOKUP($A8,INSUMOS!$A$5:$N$28,5,FALSE),0)*$E8/100 | H8: =IFERROR(VLOOKUP($A8,INSUMOS!$A$5:$N$28,6,FALSE),0)*$E8/100/100 | I8: =IFERROR(VLOOKUP($A8,INSUMOS!$A$5:$N$28,7,FALSE),0)*$E8/100 | J8: =IFERROR(VLOOKUP($A8,INSUMOS!$A$5:$N$28,8,FALSE),0)*$E8/100 | K8: =IFERROR(VLOOKUP($A8,INSUMOS!$A$5:$N$28,9,FALSE),0)*$E8/100 | L8: =IFERROR(VLOOKUP($A8,INSUMOS!$A$5:$N$28,10,FALSE),0)*$E8/100 | M8: =IFERROR(VLOOKUP($A8,INSUMOS!$A$5:$N$28,11,FALSE),0)*$E8/100 | N8: =IFERROR(VLOOKUP($A8,INSUMOS!$A$5:$N$28,12,FALSE),0)*$E8/100 | O8: =IFERROR(VLOOKUP($A8,INSUMOS!$A$5:$N$28,13,FALSE),0)*$E8/100
A9: LEITE EM PO DESNATADO ZL (BATAVO PENSE ZERO) | B9: leite em po desnatado zl (batavo pense zero) | C9: 33 | D9: =C9/SUM(C$5:C$12) | E9: 4.62 | F9: =IFERROR(VLOOKUP($A9,INSUMOS!$A$5:$N$28,4,FALSE),0)*$E9/100 | G9: =IFERROR(VLOOKUP($A9,INSUMOS!$A$5:$N$28,5,FALSE),0)*$E9/100 | H9: =IFERROR(VLOOKUP($A9,INSUMOS!$A$5:$N$28,6,FALSE),0)*$E9/100/100 | I9: =IFERROR(VLOOKUP($A9,INSUMOS!$A$5:$N$28,7,FALSE),0)*$E9/100 | J9: =IFERROR(VLOOKUP($A9,INSUMOS!$A$5:$N$28,8,FALSE),0)*$E9/100 | K9: =IFERROR(VLOOKUP($A9,INSUMOS!$A$5:$N$28,9,FALSE),0)*$E9/100 | L9: =IFERROR(VLOOKUP($A9,INSUMOS!$A$5:$N$28,10,FALSE),0)*$E9/100 | M9: =IFERROR(VLOOKUP($A9,INSUMOS!$A$5:$N$28,11,FALSE),0)*$E9/100 | N9: =IFERROR(VLOOKUP($A9,INSUMOS!$A$5:$N$28,12,FALSE),0)*$E9/100 | O9: =IFERROR(VLOOKUP($A9,INSUMOS!$A$5:$N$28,13,FALSE),0)*$E9/100
A10: POLIDEXTROSE | B10: polidextrose | C10: 20 | D10: =C10/SUM(C$5:C$12) | E10: 2.8 | F10: =IFERROR(VLOOKUP($A10,INSUMOS!$A$5:$N$28,4,FALSE),0)*$E10/100 | G10: =IFERROR(VLOOKUP($A10,INSUMOS!$A$5:$N$28,5,FALSE),0)*$E10/100 | H10: =IFERROR(VLOOKUP($A10,INSUMOS!$A$5:$N$28,6,FALSE),0)*$E10/100/100 | I10: =IFERROR(VLOOKUP($A10,INSUMOS!$A$5:$N$28,7,FALSE),0)*$E10/100 | J10: =IFERROR(VLOOKUP($A10,INSUMOS!$A$5:$N$28,8,FALSE),0)*$E10/100 | K10: =IFERROR(VLOOKUP($A10,INSUMOS!$A$5:$N$28,9,FALSE),0)*$E10/100 | L10: =IFERROR(VLOOKUP($A10,INSUMOS!$A$5:$N$28,10,FALSE),0)*$E10/100 | M10: =IFERROR(VLOOKUP($A10,INSUMOS!$A$5:$N$28,11,FALSE),0)*$E10/100 | N10: =IFERROR(VLOOKUP($A10,INSUMOS!$A$5:$N$28,12,FALSE),0)*$E10/100 | O10: =IFERROR(VLOOKUP($A10,INSUMOS!$A$5:$N$28,13,FALSE),0)*$E10/100
A11: GLICEROL (GLICERINA BIDESTILADA) | B11: umectante glicerol | C11: 15 | D11: =C11/SUM(C$5:C$12) | E11: 2.1 | F11: =IFERROR(VLOOKUP($A11,INSUMOS!$A$5:$N$28,4,FALSE),0)*$E11/100 | G11: =IFERROR(VLOOKUP($A11,INSUMOS!$A$5:$N$28,5,FALSE),0)*$E11/100 | H11: =IFERROR(VLOOKUP($A11,INSUMOS!$A$5:$N$28,6,FALSE),0)*$E11/100/100 | I11: =IFERROR(VLOOKUP($A11,INSUMOS!$A$5:$N$28,7,FALSE),0)*$E11/100 | J11: =IFERROR(VLOOKUP($A11,INSUMOS!$A$5:$N$28,8,FALSE),0)*$E11/100 | K11: =IFERROR(VLOOKUP($A11,INSUMOS!$A$5:$N$28,9,FALSE),0)*$E11/100 | L11: =IFERROR(VLOOKUP($A11,INSUMOS!$A$5:$N$28,10,FALSE),0)*$E11/100 | M11: =IFERROR(VLOOKUP($A11,INSUMOS!$A$5:$N$28,11,FALSE),0)*$E11/100 | N11: =IFERROR(VLOOKUP($A11,INSUMOS!$A$5:$N$28,12,FALSE),0)*$E11/100 | O11: =IFERROR(VLOOKUP($A11,INSUMOS!$A$5:$N$28,13,FALSE),0)*$E11/100
A12: CREMOBENE PREMIUM (LIGA NEUTRA) | B12: cremobene premium (liga neutra) | C12: 6 | D12: =C12/SUM(C$5:C$12) | E12: 0.84 | F12: =IFERROR(VLOOKUP($A12,INSUMOS!$A$5:$N$28,4,FALSE),0)*$E12/100 | G12: =IFERROR(VLOOKUP($A12,INSUMOS!$A$5:$N$28,5,FALSE),0)*$E12/100 | H12: =IFERROR(VLOOKUP($A12,INSUMOS!$A$5:$N$28,6,FALSE),0)*$E12/100/100 | I12: =IFERROR(VLOOKUP($A12,INSUMOS!$A$5:$N$28,7,FALSE),0)*$E12/100 | J12: =IFERROR(VLOOKUP($A12,INSUMOS!$A$5:$N$28,8,FALSE),0)*$E12/100 | K12: =IFERROR(VLOOKUP($A12,INSUMOS!$A$5:$N$28,9,FALSE),0)*$E12/100 | L12: =IFERROR(VLOOKUP($A12,INSUMOS!$A$5:$N$28,10,FALSE),0)*$E12/100 | M12: =IFERROR(VLOOKUP($A12,INSUMOS!$A$5:$N$28,11,FALSE),0)*$E12/100 | N12: =IFERROR(VLOOKUP($A12,INSUMOS!$A$5:$N$28,12,FALSE),0)*$E12/100 | O12: =IFERROR(VLOOKUP($A12,INSUMOS!$A$5:$N$28,13,FALSE),0)*$E12/100
A13: TOTAL NO POTE | C13: =SUM(C5:C12) | E13: =SUM(E5:E12) | F13: =SUM(F5:F12) | G13: =SUM(G5:G12) | H13: =SUM(H5:H12) | I13: =SUM(I5:I12) | J13: =SUM(J5:J12) | K13: =SUM(K5:K12) | L13: =SUM(L5:L12) | ... O13: =SUM(O5:O12)
A15: POR 100 g DE PRODUTO
A16: Componente | B16: Valor | C16: Unidade
A17: Valor energético | B17: =F13/140*100 | C17: kcal
A18: Açúcares totais (rótulo) | B18: 8.844 | C18: g
A19: dos quais adicionados | B19: =H13/140*100 | C19: g
A20: Polióis | B20: 5.777 | C20: g
A21: Fibras alimentares | B21: =M13/140*100 | C21: g
A22: Proteínas | B22: =L13/140*100 | C22: g
A23: Gorduras totais | B23: =I13/140*100 | C23: g
A24: das quais saturadas | B24: =J13/140*100 | C24: g
A25: das quais trans | B25: =K13/140*100 | C25: g
A26: Sódio | B26: =O13/140*100 | C26: mg
A27: Sólidos totais | B27: =N13/140*100 | C27: g
A28: Açúcares técnicos (uso interno) | B28: 14.621 | C28: g
A30: PARÂMETROS DA CALDA
A31: Sólidos totais | B31: 39.4 | C31: %
A32: Água | B32: 60.6 | C32: %
A33: Gordura | B33: 6.53 | C33: %
A34: Proteína | B34: 3.63 | C34: %
A35: POD | B35: 170
A36: PAC | B36: 351.85
A37: Janela de consumo | B37: -15.0 a -19.7 | C37: °C
A38: Água congelada a −8 °C | B38: 60.53 | C38: %
A40: LISTA DE INGREDIENTES — RDC 727/2022
A41: Ingredientes: leite integral zero lactose, creme de leite zero lactose, polidextrose, preparado de limão siciliano, maltitol, leite em po desnatado zl (batavo pense zero), eritritol, umectante glicerol, inulina, cremobene premium (liga neutra), edulcorante glicosídeos de esteviol.
A42: ALÉRGICOS: CONTÉM LEITE.
A43: Selos: ALTO TEOR DE FIBRAS · SEM ADIÇÃO DE AÇÚCARES
A44: Lupa frontal: nenhuma

Sheet Alfajor
A1: Alfajor
A2: linha SPECIAL · família de formulação: creme / leite · pote de 150 g
A4: Ingrediente | B4: Nome de rótulo | C4: g por kg de calda | D4: % da calda | E4: g no pote | F4: kcal | G4: Açúc. téc. | H4: Aç. adic. | I4: Gord. | J4: G.sat. | K4: G.trans | L4: Prot. | M4: Fibra | N4: Sól.tot. | O4: Sódio mg
A5: LEITE ZERO LACTOSE (INTEGRAL) | B5: leite integral zero lactose | C5: 607.7 | D5: =C5/SUM(C$5:C$14) | E5: 82.04 | F5: =IFERROR(VLOOKUP($A5,INSUMOS!$A$5:$N$28,4,FALSE),0)*$E5/100 | G5: =IFERROR(VLOOKUP($A5,INSUMOS!$A$5:$N$28,5,FALSE),0)*$E5/100 | H5: =IFERROR(VLOOKUP($A5,INSUMOS!$A$5:$N$28,6,FALSE),0)*$E5/100/100 | I5: =IFERROR(VLOOKUP($A5,INSUMOS!$A$5:$N$28,7,FALSE),0)*$E5/100 | J5: =IFERROR(VLOOKUP($A5,INSUMOS!$A$5:$N$28,8,FALSE),0)*$E5/100 | K5: =IFERROR(VLOOKUP($A5,INSUMOS!$A$5:$N$28,9,FALSE),0)*$E5/100 | L5: =IFERROR(VLOOKUP($A5,INSUMOS!$A$5:$N$28,10,FALSE),0)*$E5/100 | M5: =IFERROR(VLOOKUP($A5,INSUMOS!$A$5:$N$28,11,FALSE),0)*$E5/100 | N5: =IFERROR(VLOOKUP($A5,INSUMOS!$A$5:$N$28,12,FALSE),0)*$E5/100 | O5: =IFERROR(VLOOKUP($A5,INSUMOS!$A$5:$N$28,13,FALSE),0)*$E5/100
A6: DOCE DE LEITE VIÇOSA ZERO | B6: doce de leite viçosa zero | C6: 160 | D6: =C6/SUM(C$5:C$14) | E6: 21.6 | F6: =IFERROR(VLOOKUP($A6,INSUMOS!$A$5:$N$28,4,FALSE),0)*$E6/100 | G6: =IFERROR(VLOOKUP($A6,INSUMOS!$A$5:$N$28,5,FALSE),0)*$E6/100 | H6: =IFERROR(VLOOKUP($A6,INSUMOS!$A$5:$N$28,6,FALSE),0)*$E6/100/100 | I6: =IFERROR(VLOOKUP($A6,INSUMOS!$A$5:$N$28,7,FALSE),0)*$E6/100 | J6: =IFERROR(VLOOKUP($A6,INSUMOS!$A$5:$N$28,8,FALSE),0)*$E6/100 | K6: =IFERROR(VLOOKUP($A6,INSUMOS!$A$5:$N$28,9,FALSE),0)*$E6/100 | L6: =IFERROR(VLOOKUP($A6,INSUMOS!$A$5:$N$28,10,FALSE),0)*$E6/100 | M6: =IFERROR(VLOOKUP($A6,INSUMOS!$A$5:$N$28,11,FALSE),0)*$E6/100 | N6: =IFERROR(VLOOKUP($A6,INSUMOS!$A$5:$N$28,12,FALSE),0)*$E6/100 | O6: =IFERROR(VLOOKUP($A6,INSUMOS!$A$5:$N$28,13,FALSE),0)*$E6/100
A7: POLIDEXTROSE | B7: polidextrose | C7: 70 | D7: =C7/SUM(C$5:C$14) | E7: 9.45 | F7: =IFERROR(VLOOKUP($A7,INSUMOS!$A$5:$N$28,4,FALSE),0)*$E7/100 | G7: =IFERROR(VLOOKUP($A7,INSUMOS!$A$5:$N$28,5,FALSE),0)*$E7/100 | H7: =IFERROR(VLOOKUP($A7,INSUMOS!$A$5:$N$28,6,FALSE),0)*$E7/100/100 | I7: =IFERROR(VLOOKUP($A7,INSUMOS!$A$5:$N$28,7,FALSE),0)*$E7/100 | J7: =IFERROR(VLOOKUP($A7,INSUMOS!$A$5:$N$28,8,FALSE),0)*$E7/100 | K7: =IFERROR(VLOOKUP($A7,INSUMOS!$A$5:$N$28,9,FALSE),0)*$E7/100 | L7: =IFERROR(VLOOKUP($A7,INSUMOS!$A$5:$N$28,10,FALSE),0)*$E7/100 | M7: =IFERROR(VLOOKUP($A7,INSUMOS!$A$5:$N$28,11,FALSE),0)*$E7/100 | N7: =IFERROR(VLOOKUP($A7,INSUMOS!$A$5:$N$28,12,FALSE),0)*$E7/100 | O7: =IFERROR(VLOOKUP($A7,INSUMOS!$A$5:$N$28,13,FALSE),0)*$E7/100
A8: CREME DE LEITE FRESCO 35% ZL (VERDE CAMPO LACFREE) | B8: creme de leite zero lactose | C8: 60 | D8: =C8/SUM(C$5:C$14) | E8: 8.1 | F8: =IFERROR(VLOOKUP($A8,INSUMOS!$A$5:$N$28,4,FALSE),0)*$E8/100 | G8: =IFERROR(VLOOKUP($A8,INSUMOS!$A$5:$N$28,5,FALSE),0)*$E8/100 | H8: =IFERROR(VLOOKUP($A8,INSUMOS!$A$5:$N$28,6,FALSE),0)*$E8/100/100 | I8: =IFERROR(VLOOKUP($A8,INSUMOS!$A$5:$N$28,7,FALSE),0)*$E8/100 | J8: =IFERROR(VLOOKUP($A8,INSUMOS!$A$5:$N$28,8,FALSE),0)*$E8/100 | K8: =IFERROR(VLOOKUP($A8,INSUMOS!$A$5:$N$28,9,FALSE),0)*$E8/100 | L8: =IFERROR(VLOOKUP($A8,INSUMOS!$A$5:$N$28,10,FALSE),0)*$E8/100 | M8: =IFERROR(VLOOKUP($A8,INSUMOS!$A$5:$N$28,11,FALSE),0)*$E8/100 | N8: =IFERROR(VLOOKUP($A8,INSUMOS!$A$5:$N$28,12,FALSE),0)*$E8/100 | O8: =IFERROR(VLOOKUP($A8,INSUMOS!$A$5:$N$28,13,FALSE),0)*$E8/100
A9: LEITE EM PO DESNATADO ZL (BATAVO PENSE ZERO) | B9: leite em po desnatado zl (batavo pense zero) | C9: 50 | D9: =C9/SUM(C$5:C$14) | E9: 6.75 | F9: =IFERROR(VLOOKUP($A9,INSUMOS!$A$5:$N$28,4,FALSE),0)*$E9/100 | G9: =IFERROR(VLOOKUP($A9,INSUMOS!$A$5:$N$28,5,FALSE),0)*$E9/100 | H9: =IFERROR(VLOOKUP($A9,INSUMOS!$A$5:$N$28,6,FALSE),0)*$E9/100/100 | I9: =IFERROR(VLOOKUP($A9,INSUMOS!$A$5:$N$28,7,FALSE),0)*$E9/100 | J9: =IFERROR(VLOOKUP($A9,INSUMOS!$A$5:$N$28,8,FALSE),0)*$E9/100 | K9: =IFERROR(VLOOKUP($A9,INSUMOS!$A$5:$N$28,9,FALSE),0)*$E9/100 | L9: =IFERROR(VLOOKUP($A9,INSUMOS!$A$5:$N$28,10,FALSE),0)*$E9/100 | M9: =IFERROR(VLOOKUP($A9,INSUMOS!$A$5:$N$28,11,FALSE),0)*$E9/100 | N9: =IFERROR(VLOOKUP($A9,INSUMOS!$A$5:$N$28,12,FALSE),0)*$E9/100 | O9: =IFERROR(VLOOKUP($A9,INSUMOS!$A$5:$N$28,13,FALSE),0)*$E9/100
A10: MALTITOL | B10: maltitol | C10: 30 | D10: =C10/SUM(C$5:C$14) | E10: 4.05 | F10: =IFERROR(VLOOKUP($A10,INSUMOS!$A$5:$N$28,4,FALSE),0)*$E10/100 | G10: =IFERROR(VLOOKUP($A10,INSUMOS!$A$5:$N$28,5,FALSE),0)*$E10/100 | H10: =IFERROR(VLOOKUP($A10,INSUMOS!$A$5:$N$28,6,FALSE),0)*$E10/100/100 | I10: =IFERROR(VLOOKUP($A10,INSUMOS!$A$5:$N$28,7,FALSE),0)*$E10/100 | J10: =IFERROR(VLOOKUP($A10,INSUMOS!$A$5:$N$28,8,FALSE),0)*$E10/100 | K10: =IFERROR(VLOOKUP($A10,INSUMOS!$A$5:$N$28,9,FALSE),0)*$E10/100 | L10: =IFERROR(VLOOKUP($A10,INSUMOS!$A$5:$N$28,10,FALSE),0)*$E10/100 | M10: =IFERROR(VLOOKUP($A10,INSUMOS!$A$5:$N$28,11,FALSE),0)*$E10/100 | N10: =IFERROR(VLOOKUP($A10,INSUMOS!$A$5:$N$28,12,FALSE),0)*$E10/100 | O10: =IFERROR(VLOOKUP($A10,INSUMOS!$A$5:$N$28,13,FALSE),0)*$E10/100
A11: GLICEROL (GLICERINA BIDESTILADA) | B11: umectante glicerol | C11: 15 | D11: =C11/SUM(C$5:C$14) | E11: 2.025 | F11: =IFERROR(VLOOKUP($A11,INSUMOS!$A$5:$N$28,4,FALSE),0)*$E11/100 | G11: =IFERROR(VLOOKUP($A11,INSUMOS!$A$5:$N$28,5,FALSE),0)*$E11/100 | H11: =IFERROR(VLOOKUP($A11,INSUMOS!$A$5:$N$28,6,FALSE),0)*$E11/100/100 | I11: =IFERROR(VLOOKUP($A11,INSUMOS!$A$5:$N$28,7,FALSE),0)*$E11/100 | J11: =IFERROR(VLOOKUP($A11,INSUMOS!$A$5:$N$28,8,FALSE),0)*$E11/100 | K11: =IFERROR(VLOOKUP($A11,INSUMOS!$A$5:$N$28,9,FALSE),0)*$E11/100 | L11: =IFERROR(VLOOKUP($A11,INSUMOS!$A$5:$N$28,10,FALSE),0)*$E11/100 | M11: =IFERROR(VLOOKUP($A11,INSUMOS!$A$5:$N$28,11,FALSE),0)*$E11/100 | N11: =IFERROR(VLOOKUP($A11,INSUMOS!$A$5:$N$28,12,FALSE),0)*$E11/100 | O11: =IFERROR(VLOOKUP($A11,INSUMOS!$A$5:$N$28,13,FALSE),0)*$E11/100
A12: CREMOBENE PREMIUM (LIGA NEUTRA) | B12: cremobene premium (liga neutra) | C12: 6 | D12: =C12/SUM(C$5:C$14) | E12: 0.81 | F12: =IFERROR(VLOOKUP($A12,INSUMOS!$A$5:$N$28,4,FALSE),0)*$E12/100 | G12: =IFERROR(VLOOKUP($A12,INSUMOS!$A$5:$N$28,5,FALSE),0)*$E12/100 | H12: =IFERROR(VLOOKUP($A12,INSUMOS!$A$5:$N$28,6,FALSE),0)*$E12/100/100 | I12: =IFERROR(VLOOKUP($A12,INSUMOS!$A$5:$N$28,7,FALSE),0)*$E12/100 | J12: =IFERROR(VLOOKUP($A12,INSUMOS!$A$5:$N$28,8,FALSE),0)*$E12/100 | K12: =IFERROR(VLOOKUP($A12,INSUMOS!$A$5:$N$28,9,FALSE),0)*$E12/100 | L12: =IFERROR(VLOOKUP($A12,INSUMOS!$A$5:$N$28,10,FALSE),0)*$E12/100 | M12: =IFERROR(VLOOKUP($A12,INSUMOS!$A$5:$N$28,11,FALSE),0)*$E12/100 | N12: =IFERROR(VLOOKUP($A12,INSUMOS!$A$5:$N$28,12,FALSE),0)*$E12/100 | O12: =IFERROR(VLOOKUP($A12,INSUMOS!$A$5:$N$28,13,FALSE),0)*$E12/100
A13: SAL | B13: sal | C13: 1 | D13: =C13/SUM(C$5:C$14) | E13: 0.135 | F13: =IFERROR(VLOOKUP($A13,INSUMOS!$A$5:$N$28,4,FALSE),0)*$E13/100 | G13: =IFERROR(VLOOKUP($A13,INSUMOS!$A$5:$N$28,5,FALSE),0)*$E13/100 | H13: =IFERROR(VLOOKUP($A13,INSUMOS!$A$5:$N$28,6,FALSE),0)*$E13/100/100 | I13: =IFERROR(VLOOKUP($A13,INSUMOS!$A$5:$N$28,7,FALSE),0)*$E13/100 | J13: =IFERROR(VLOOKUP($A13,INSUMOS!$A$5:$N$28,8,FALSE),0)*$E13/100 | K13: =IFERROR(VLOOKUP($A13,INSUMOS!$A$5:$N$28,9,FALSE),0)*$E13/100 | L13: =IFERROR(VLOOKUP($A13,INSUMOS!$A$5:$N$28,10,FALSE),0)*$E13/100 | M13: =IFERROR(VLOOKUP($A13,INSUMOS!$A$5:$N$28,11,FALSE),0)*$E13/100 | N13: =IFERROR(VLOOKUP($A13,INSUMOS!$A$5:$N$28,12,FALSE),0)*$E13/100 | O13: =IFERROR(VLOOKUP($A13,INSUMOS!$A$5:$N$28,13,FALSE),0)*$E13/100
A14: STEVIA | B14: edulcorante glicosídeos de esteviol | C14: 0.3 | D14: =C14/SUM(C$5:C$14) | E14: 0.04 | F14: =IFERROR(VLOOKUP($A14,INSUMOS!$A$5:$N$28,4,FALSE),0)*$E14/100 | G14: =IFERROR(VLOOKUP($A14,INSUMOS!$A$5:$N$28,5,FALSE),0)*$E14/100 | H14: =IFERROR(VLOOKUP($A14,INSUMOS!$A$5:$N$28,6,FALSE),0)*$E14/100/100 | I14: =IFERROR(VLOOKUP($A14,INSUMOS!$A$5:$N$28,7,FALSE),0)*$E14/100 | J14: =IFERROR(VLOOKUP($A14,INSUMOS!$A$5:$N$28,8,FALSE),0)*$E14/100 | K14: =IFERROR(VLOOKUP($A14,INSUMOS!$A$5:$N$28,9,FALSE),0)*$E14/100 | L14: =IFERROR(VLOOKUP($A14,INSUMOS!$A$5:$N$28,10,FALSE),0)*$E14/100 | M14: =IFERROR(VLOOKUP($A14,INSUMOS!$A$5:$N$28,11,FALSE),0)*$E14/100 | N14: =IFERROR(VLOOKUP($A14,INSUMOS!$A$5:$N$28,12,FALSE),0)*$E14/100 | O14: =IFERROR(VLOOKUP($A14,INSUMOS!$A$5:$N$28,13,FALSE),0)*$E14/100
A15: BISCOITO ALFAJOR DE CHOCOLATE (ZERO LACTOSE) | B15: biscoito de alfajor de chocolate | C15: 111 | D15: =C15/SUM(C$5:C$14) | E15: 14.985 | F15: =IFERROR(VLOOKUP($A15,INSUMOS!$A$5:$N$28,4,FALSE),0)*$E15/100 | G15: =IFERROR(VLOOKUP($A15,INSUMOS!$A$5:$N$28,5,FALSE),0)*$E15/100 | H15: =IFERROR(VLOOKUP($A15,INSUMOS!$A$5:$N$28,6,FALSE),0)*$E15/100/100 | I15: =IFERROR(VLOOKUP($A15,INSUMOS!$A$5:$N$28,7,FALSE),0)*$E15/100 | J15: =IFERROR(VLOOKUP($A15,INSUMOS!$A$5:$N$28,8,FALSE),0)*$E15/100 | K15: =IFERROR(VLOOKUP($A15,INSUMOS!$A$5:$N$28,9,FALSE),0)*$E15/100 | L15: =IFERROR(VLOOKUP($A15,INSUMOS!$A$5:$N$28,10,FALSE),0)*$E15/100 | M15: =IFERROR(VLOOKUP($A15,INSUMOS!$A$5:$N$28,11,FALSE),0)*$E15/100 | N15: =IFERROR(VLOOKUP($A15,INSUMOS!$A$5:$N$28,12,FALSE),0)*$E15/100 | O15: =IFERROR(VLOOKUP($A15,INSUMOS!$A$5:$N$28,13,FALSE),0)*$E15/100
A16: TOTAL NO POTE | C16: =SUM(C5:C14) | E16: =SUM(E5:E15) | F16: =SUM(F5:F15) | G16: =SUM(G5:G15) | H16: =SUM(H5:H15) | I16: =SUM(I5:I15) | J16: =SUM(J5:J15) | K16: =SUM(K5:K15) | L16: =SUM(L5:L15) | ... O16: =SUM(O5:O15)
A18: POR 100 g DE PRODUTO
A19: Componente | B19: Valor | C19: Unidade
A20: Valor energético | B20: =F16/149.98499999999999*100 | C20: kcal
A21: Açúcares totais (rótulo) | B21: 7.777 | C21: g
A22: dos quais adicionados | B22: =H16/149.98499999999999*100 | C22: g
A23: Polióis | B23: 6.403 | C23: g
A24: Fibras alimentares | B24: =M16/149.98499999999999*100 | C24: g
A25: Proteínas | B25: =L16/149.98499999999999*100 | C25: g
A26: Gorduras totais | B26: =I16/149.98499999999999*100 | C26: g
A27: das quais saturadas | B27: =J16/149.98499999999999*100 | C27: g
A28: das quais trans | B28: =K16/149.98499999999999*100 | C28: g
A29: Sódio | B29: =O16/149.98499999999999*100 | C29: mg
A30: Sólidos totais | B30: =N16/149.98499999999999*100 | C30: g
A31: Açúcares técnicos (uso interno) | B31: 14.18 | C31: g
A33: PARÂMETROS DA CALDA
A34: Sólidos totais | B34: 37.13 | C34: %
A35: Água | B35: 62.87 | C35: %
A36: Gordura | B36: 6.14 | C36: %
A37: Proteína | B37: 5.37 | C37: %
A38: POD | B38: 147.92
A39: PAC | B39: 369
A40: Janela de consumo | B40: -15.2 a -20.0 | C40: °C
