Workbook

Sheet LEIA-ME
B2: O BECO GELATO — COMPRAS E ESTOQUE
B3: 22 de outubro de 2026
B6: O QUE TEM AQUI
B7: PLANO DE PRODUCAO — voce diz quantos potes de cada sabor pretende fazer. Tudo o resto se recalcula a partir daqui.
B8: FORNECEDORES — cada insumo, de quem vem, embalagem e preco por quilo.
B9: ESTOQUE INSUMOS — o que tem contra o que o plano exige, com a falta e o custo de cobrir a falta.
B10: EMBALAGEM — pote, colher e lacre, e quantos potes cada saldo ainda fecha.
B11: POTES PRONTOS — estoque de produto acabado por sabor, com entradas e saidas.
B12: TESTES — cada calda que voce bateu para testar ou para comer, com o custo, e a verba mensal de P&D.
B13: MOVIMENTO — onde voce lanca cada producao e cada venda. E a unica aba que precisa de disciplina diaria.
B15: A COR DIZ SE PODE MEXER
B16: AMARELO — campo seu. Digite.
... B41: O custo por quilo eu tenho para quase todas, porque as receitas estao cadastradas. O que falta e o VOLUME: eu so sei os kg que voce declarou em voz alta — 1,5 kg do pistache meia a meia, 750 g da base neutra, 1 kg do melagrana e 1 kg da canela. Os outros ficaram em branco de proposito, porque chutar quilo ali estragaria exatamente a media que voce quer usar para fixar a verba.

Sheet PLANO
A1: PLANO DE PRODUCAO
A2: Quantos potes de cada sabor voce quer produzir no periodo. Esta aba comanda ESTOQUE INSUMOS e EMBALAGEM.
A4: PERIODO DO PLANO | B4: 30 dias
A6: SABOR | B6: POTES A PRODUZIR | C6: CALDA NECESSARIA (kg) | D6: PRECO DE VENDA (R$) | E6: RECEITA PREVISTA (R$)
A7: Café Proteico | B7: 30 | C7: =B7*0.1443 | D7: 20.5 | E7: =B7*D7
A8: Pistache | B8: 30 | C8: =B8*0.1443 | D8: 20.5 | E8: =B8*D8
A9: Manga com Maracujá | B9: 30 | C9: =B9*0.1331 | D9: 18.7 | E9: =B9*D9
A10: Sorbet Morango | B10: 30 | C10: =B10*0.1116 | D10: 18.7 | E10: =B10*D10
A11: Torta de Limão | B11: 30 | C11: =B11*0.1443 | D11: 20.5 | E11: =B11*D11
A12: Alfajor | B12: 30 | C12: =B12*0.1546 | D12: 20.5 | E12: =B12*D12
A13: Brigadeiro Proteico | B13: 30 | C13: =B13*0.1443 | D13: 20.5 | E13: =B13*D13
A14: TOTAL | B14: =SUM(B7:B13) | C14: =SUM(C7:C13) | E14: =SUM(E7:E13)
A16: A calda necessaria ja inclui a perda de 3% e exclui a agua das receitas de fruta.

Sheet FORNECEDORES
A1: FORNECEDORES E PRECOS
A2: O sistema nunca teve cadastro de fornecedor. Preenchi o que saiu das conversas e marquei a procedencia. As linhas vazias sao para voce.
A4: INSUMO | B4: FORNECEDOR | C4: MARCA | D4: EMBALAGEM | E4: R$/kg ATUAL | F4: R$/kg COTADO | G4: ECONOMIA | H4: CONTATO / TELEFONE | I4: PRAZO (dias) | J4: ORIGEM DO DADO / OBS
A5: BASE MEC PROTEIN | B5: MEC3 | C5: Base MEC Protein | E5: 148.2 | G5: =IF(F5="","",E5-F5) | J5: ficha
A6: BISCOITO ALFAJOR DE CHOCOLATE (ZERO LACTOSE) | D6: caixa 4 un | E6: 38.46 | G6: =IF(F6="","",E6-F6) | J6: nota 8,00/4 un
A7: CACAU 22/24 | E7: 130 | G7: =IF(F7="","",E7-F7)
A8: CREME DE LEITE FRESCO 35% ZL (VERDE CAMPO LACFREE) | B8: Verde Campo | C8: Lacfree | D8: 500 g | E8: 57.8 | G8: =IF(F8="","",E8-F8) | J8: nota 28,90/500 g
A9: CREMOBENE PREMIUM (LIGA NEUTRA) | B9: Biobene | C9: Cremobene Premium | E9: 105.84 | G9: =IF(F9="","",E9-F9) | J9: conversa
A10: DELÍCIA DE AMENDOIM PROTEICO | E10: 94.25 | G10: =IF(F10="","",E10-F10) | J10: —
A11: DOCE DE LEITE VIÇOSA ZERO | B11: Viçosa | C11: Viçosa Zero | D11: pote 400 g | E11: 99.75 | G11: =IF(F11="","",E11-F11) | J11: nota 39,90/400 g
A12: ERITRITOL | D12: 1 kg | E12: 53.76 | F12: 14.75 | G12: =IF(F12="","",E12-F12) | J12: cotação Huakang 25 kg R$ 14,75
A13: GLICEROL (GLICERINA BIDESTILADA) | E13: 24 | G13: =IF(F13="","",E13-F13)
A14: GUSTO LIMONE SICILIA (PÓ) | B14: MEC3 | C14: Gusto Limone Sicilia | E14: 359.62 | G14: =IF(F14="","",E14-F14) | J14: ficha
A15: INULINA | E15: 90 | G15: =IF(F15="","",E15-F15)
A16: LEITE EM PO DESNATADO ZL (BATAVO PENSE ZERO) | B16: Batavo | C16: Pense Zero | E16: 65.7 | G16: =IF(F16="","",E16-F16) | J16: conversa
A17: LEITE ZERO LACTOSE (INTEGRAL) | B17: Leitíssimo | E17: 9.8 | G17: =IF(F17="","",E17-F17) | J17: conversa
A18: MALTITOL | E18: 37.78 | F18: 17.95 | G18: =IF(F18="","",E18-F18) | J18: cotação Yusweet 25 kg R$ 17,95
A19: MANGA | E19: 22 | G19: =IF(F19="","",E19-F19)
A20: MARACUJA (POLPA) | E20: 30 | G20: =IF(F20="","",E20-F20)
A21: MORANGO | E21: 11.29 | G21: =IF(F21="","",E21-F21)
A22: PASTA CAFÉ SELECTA (BALDE 2 KG) | C22: Selecta | D22: balde 2 kg | E22: 90 | G22: =IF(F22="","",E22-F22) | J22: conversa
A23: PASTA FRAGOLA MEC3 (18047) | B23: MEC3 | C23: MEC3 18047 | E23: 142.27 | G23: =IF(F23="","",E23-F23) | J23: ficha
A24: PASTA PISTACCHIO 100% CALIFÓRNIA | E24: 450 | G24: =IF(F24="","",E24-F24) | J24: —
A25: POLIDEXTROSE | D25: 10 kg | E25: 28.92 | F25: 12.85 | G25: =IF(F25="","",E25-F25) | J25: cotação Bailong 25 kg R$ 12,85
A26: SAL | E26: 3 | G26: =IF(F26="","",E26-F26)
A27: STEVIA | E27: 3100 | G27: =IF(F27="","",E27-F27)
A29: COTACAO DE 21/10/2026 — AINDA NAO COMPRADA
A30: Eritritol — Huakang — saco 25 kg — R$ 14,75/kg — ICMS 12% incluso
A31: Maltitol — Yusweet — saco 25 kg — R$ 17,95/kg — ICMS 4% incluso
A32: Polidextrose — Shandong Bailong — saco 25 kg — R$ 12,85/kg — ICMS 12% incluso
A34: Com os tres, o Mix Oficial cai de R$ 49,13 para R$ 29,83/kg e o CMV medio cai cerca de R$ 0,35 por pote.
A35: Pendente antes de fechar: ficha tecnica dos tres, granulometria do eritritol e data de fabricacao / validade.
A36: A polidextrose e o limitante: 25 kg dao cerca de 2.380 potes, contra 7.300 do maltitol e 9.160 do eritritol.

Sheet ESTOQUE INSUMOS
A1: ESTOQUE ATUAL x NECESSARIO
A2: O necessario vem da aba PLANO. Atualize a coluna ATUAL depois de cada contagem.
A4: INSUMO | B4: ESTOQUE ATUAL (g) | C4: NECESSARIO PLANO (g) | D4: SALDO (g) | E4: COMPRAR (kg) | F4: R$/kg | G4: CUSTO DA COMPRA (R$) | H4: SITUACAO
A5: BASE MEC PROTEIN | B5: 11500 | C5: =PLANO!B7*15.9216+PLANO!B13*18.0412 | D5: =B5-C5 | E5: =IF(D5>=0,0,ROUNDUP(-D5/1000,3)) | F5: =FORNECEDORES!E5 | G5: =E5*F5 | H5: =IF(B5=0,"SEM ESTOQUE",IF(D5<0,"FALTA","ok"))
A6: BISCOITO ALFAJOR DE CHOCOLATE (ZERO LACTOSE) | B6: 0 | C6: =PLANO!B12*15.4485 | D6: =B6-C6 | E6: =IF(D6>=0,0,ROUNDUP(-D6/1000,3)) | F6: =FORNECEDORES!E6 | G6: =E6*F6 | H6: =IF(B6=0,"SEM ESTOQUE",IF(D6<0,"FALTA","ok"))
A7: CACAU 22/24 | B7: 0 | C7: =PLANO!B13*5.5567 | D7: =B7-C7 | E7: =IF(D7>=0,0,ROUNDUP(-D7/1000,3)) | F7: =FORNECEDORES!E7 | G7: =E7*F7 | H7: =IF(B7=0,"SEM ESTOQUE",IF(D7<0,"FALTA","ok"))
A8: CREME DE LEITE FRESCO 35% ZL (VERDE CAMPO LACFREE) | B8: 1500 | C8: =PLANO!B8*8.9485+PLANO!B11*14.7216+PLANO!B12*8.3505 | D8: =B8-C8 | E8: =IF(D8>=0,0,ROUNDUP(-D8/1000,3)) | F8: =FORNECEDORES!E8 | G8: =E8*F8 | H8: =IF(B8=0,"SEM ESTOQUE",IF(D8<0,"FALTA","ok"))
A9: CREMOBENE PREMIUM (LIGA NEUTRA) | B9: 1989.8 | C9: =PLANO!B7*0.3754+PLANO!B8*0.7505+PLANO!B9*0.4330+PLANO!B10*0.3711+PLANO!B11*0.8660+PLANO!B12*0.8351+PLANO!B13*0.4330 | D9: =B9-C9 | E9: =IF(D9>=0,0,ROUNDUP(-D9/1000,3)) | F9: =FORNECEDORES!E9 | G9: =E9*F9 | H9: =IF(B9=0,"SEM ESTOQUE",IF(D9<0,"FALTA","ok"))
A10: DELÍCIA DE AMENDOIM PROTEICO | B10: 1627 | C10: =PLANO!B7*14.8860 | D10: =B10-C10 | E10: =IF(D10>=0,0,ROUNDUP(-D10/1000,3)) | F10: =FORNECEDORES!E10 | G10: =E10*F10 | H10: =IF(B10=0,"SEM ESTOQUE",IF(D10<0,"FALTA","ok"))
A11: DOCE DE LEITE VIÇOSA ZERO | B11: 0 | C11: =PLANO!B12*22.2680 | D11: =B11-C11 | E11: =IF(D11>=0,0,ROUNDUP(-D11/1000,3)) | F11: =FORNECEDORES!E11 | G11: =E11*F11 | H11: =IF(B11=0,"SEM ESTOQUE",IF(D11<0,"FALTA","ok"))
A12: ERITRITOL | B12: 5000 | C12: =PLANO!B8*5.7125+PLANO!B9*2.8259+PLANO!B10*6.4983+PLANO!B11*3.5324 | D12: =B12-C12 | E12: =IF(D12>=0,0,ROUNDUP(-D12/1000,3)) | F12: =FORNECEDORES!E12 | G12: =E12*F12 | H12: =IF(B12=0,"SEM ESTOQUE",IF(D12<0,"FALTA","ok"))
A13: GLICEROL (GLICERINA BIDESTILADA) | B13: 900 | C13: =PLANO!B7*3.6762+PLANO!B8*2.1649+PLANO!B9*2.1649+PLANO!B10*1.8557+PLANO!B11*2.1649+PLANO!B12*2.0876+PLANO!B13*4.1711 | D13: =B13-C13 | E13: =IF(D13>=0,0,ROUNDUP(-D13/1000,3)) | F13: =FORNECEDORES!E13 | G13: =E13*F13 | H13: =IF(B13=0,"SEM ESTOQUE",IF(D13<0,"FALTA","ok"))
A14: GUSTO LIMONE SICILIA (PÓ) | B14: 1917.7 | C14: =PLANO!B11*8.6598 | D14: =B14-C14 | E14: =IF(D14>=0,0,ROUNDUP(-D14/1000,3)) | F14: =FORNECEDORES!E14 | G14: =E14*F14 | H14: =IF(B14=0,"SEM ESTOQUE",IF(D14<0,"FALTA","ok"))
A15: INULINA | B15: 600 | C15: =PLANO!B8*1.4043+PLANO!B9*1.4043+PLANO!B10*2.3070+PLANO!B11*1.7554 | D15: =B15-C15 | E15: =IF(D15>=0,0,ROUNDUP(-D15/1000,3)) | F15: =FORNECEDORES!E15 | G15: =E15*F15 | H15: =IF(B15=0,"SEM ESTOQUE",IF(D15<0,"FALTA","ok"))
A16: LEITE EM PO DESNATADO ZL (BATAVO PENSE ZERO) | B16: 0 | C16: =PLANO!B7*14.6919+PLANO!B8*4.7629+PLANO!B11*4.7629+PLANO!B12*6.9588+PLANO!B13*16.6557 | D16: =B16-C16 | E16: =IF(D16>=0,0,ROUNDUP(-D16/1000,3)) | F16: =FORNECEDORES!E16 | G16: =E16*F16 | H16: =IF(B16=0,"SEM ESTOQUE",IF(D16<0,"FALTA","ok"))
A17: LEITE ZERO LACTOSE (INTEGRAL) | B17: 6000 | C17: =PLANO!B7*84.7857+PLANO!B8*94.5072+PLANO!B11*88.6186+PLANO!B12*84.5768+PLANO!B13*96.4845 | D17: =B17-C17 | E17: =IF(D17>=0,0,ROUNDUP(-D17/1000,3)) | F17: =FORNECEDORES!E17 | G17: =E17*F17 | H17: =IF(B17=0,"SEM ESTOQUE",IF(D17<0,"FALTA","ok"))
A18: MALTITOL | B18: 0 | C18: =PLANO!B8*3.8835+PLANO!B9*3.8835+PLANO!B10*6.3800+PLANO!B11*4.8543+PLANO!B12*4.1753 | D18: =B18-C18 | E18: =IF(D18>=0,0,ROUNDUP(-D18/1000,3)) | F18: =FORNECEDORES!E18 | G18: =E18*F18 | H18: =IF(B18=0,"SEM ESTOQUE",IF(D18<0,"FALTA","ok"))
A19: MANGA | B19: 0 | C19: =PLANO!B9*69.1340 | D19: =B19-C19 | E19: =IF(D19>=0,0,ROUNDUP(-D19/1000,3)) | F19: =FORNECEDORES!E19 | G19: =E19*F19 | H19: =IF(B19=0,"SEM ESTOQUE",IF(D19<0,"FALTA","ok"))
A20: MARACUJA (POLPA) | B20: 0 | C20: =PLANO!B9*33.9175 | D20: =B20-C20 | E20: =IF(D20>=0,0,ROUNDUP(-D20/1000,3)) | F20: =FORNECEDORES!E20 | G20: =E20*F20 | H20: =IF(B20=0,"SEM ESTOQUE",IF(D20<0,"FALTA","ok"))
A21: MORANGO | B21: 0 | C21: =PLANO!B10*77.8144 | D21: =B21-C21 | E21: =IF(D21>=0,0,ROUNDUP(-D21/1000,3)) | F21: =FORNECEDORES!E21 | G21: =E21*F21 | H21: =IF(B21=0,"SEM ESTOQUE",IF(D21<0,"FALTA","ok"))
A22: PASTA CAFÉ SELECTA (BALDE 2 KG) | B22: 0 | C22: =PLANO!B7*7.3524 | D22: =B22-C22 | E22: =IF(D22>=0,0,ROUNDUP(-D22/1000,3)) | F22: =FORNECEDORES!E22 | G22: =E22*F22 | H22: =IF(B22=0,"SEM ESTOQUE",IF(D22<0,"FALTA","ok"))
A23: PASTA FRAGOLA MEC3 (18047) | B23: 2962 | C23: =PLANO!B10*1.2371 | D23: =B23-C23 | E23: =IF(D23>=0,0,ROUNDUP(-D23/1000,3)) | F23: =FORNECEDORES!E23 | G23: =E23*F23 | H23: =IF(B23=0,"SEM ESTOQUE",IF(D23<0,"FALTA","ok"))
A24: PASTA PISTACCHIO 100% CALIFÓRNIA | B24: 2280 | C24: =PLANO!B8*12.9897 | D24: =B24-C24 | E24: =IF(D24>=0,0,ROUNDUP(-D24/1000,3)) | F24: =FORNECEDORES!E24 | G24: =E24*F24 | H24: =IF(B24=0,"SEM ESTOQUE",IF(D24<0,"FALTA","ok"))
A25: POLIDEXTROSE | B25: 11000 | C25: =PLANO!B7*2.4465+PLANO!B8*9.1539+PLANO!B9*19.2570+PLANO!B10*15.0385+PLANO!B11*14.3290+PLANO!B12*9.7423+PLANO!B13*2.7711 | D25: =B25-C25 | E25: =IF(D25>=0,0,ROUNDUP(-D25/1000,3)) | F25: =FORNECEDORES!E25 | G25: =E25*F25 | H25: =IF(B25=0,"SEM ESTOQUE",IF(D25<0,"FALTA","ok"))
A26: SAL | B26: 0 | C26: =PLANO!B7*0.1165+PLANO!B12*0.1392+PLANO!B13*0.1443 | D26: =B26-C26 | E26: =IF(D26>=0,0,ROUNDUP(-D26/1000,3)) | F26: =FORNECEDORES!E26 | G26: =E26*F26 | H26: =IF(B26=0,"SEM ESTOQUE",IF(D26<0,"FALTA","ok"))
A27: STEVIA | B27: 0 | C27: =PLANO!B7*0.0777+PLANO!B8*0.0520+PLANO!B9*0.0520+PLANO!B10*0.0854+PLANO!B11*0.0650+PLANO!B12*0.0418+PLANO!B13*0.0866 | D27: =B27-C27 | E27: =IF(D27>=0,0,ROUNDUP(-D27/1000,3)) | F27: =FORNECEDORES!E27 | G27: =E27*F27 | H27: =IF(B27=0,"SEM ESTOQUE",IF(D27<0,"FALTA","ok"))
A28: TOTAL A COMPRAR | G28: =SUM(G5:G27)
A30: O Mix Oficial nao aparece como linha: ele e feito na casa. O que esta aqui sao os cinco insumos que voce compra de fato — polidextrose, maltitol, eritritol, inulina e stevia — ja na proporcao do mix (528/224/163/81/3).
A31: A agua tambem nao aparece, por motivo obvio.
A32: A coluna NECESSARIO ja inclui a perda de 3%.
A33: A coluna COMPRAR e a necessidade liquida, nao o pedido. Ninguem compra 15 g de stevia nem 0,67 kg de doce de leite: voce compra o pacote fechado. Use a coluna como piso e arredonde para a embalagem do fornecedor.

Sheet EMBALAGEM
A1: EMBALAGEM
A2: Quantos potes cada saldo ainda fecha. O menor numero da coluna ALCANCE e o seu gargalo real de producao.
A4: ITEM | B4: POR POTE | C4: SALDO (un) | D4: ALCANCE (potes) | E4: NECESSARIO PLANO (un) | F4: COMPRAR (un) | G4: CUSTO (R$) | H4: OBS
A5: Pote 150 ml com tampa | B5: 1 | C5: 1217 | D5: =IF(B5=0,"—",FLOOR(C5/B5,1)) | E5: =B5*PLANO!B14 | F5: =MAX(0,E5-C5) | G5: =F5*1.07 | H5: R$ 0,47 negociado em 08/10 — so vale depois que este estoque acabar
A6: Colher tradicional | B6: 1 | C6: 4217 | D6: =IF(B6=0,"—",FLOOR(C6/B6,1)) | E6: =B6*PLANO!B14 | F6: =MAX(0,E6-C6) | G6: =F6*0.26
A7: Lacre de sabor | B7: 1 | C7: 717 | D7: =IF(B7=0,"—",FLOOR(C7/B7,1)) | E7: =B7*PLANO!B14 | F7: =MAX(0,E7-C7) | G7: =F7*0.34 | H7: GARGALO — menor alcance dos tres
A8: Pote 80 ml (amostra) | B8: 0 | C8: 2000 | D8: =IF(B8=0,"—",FLOOR(C8/B8,1)) | E8: =B8*PLANO!B14 | F8: =MAX(0,E8-C8) | G8: =F8*0 | H8: amostra, nao entra no pote de venda
A9: Colher de amostra | B9: 0 | C9: 5000 | D9: =IF(B9=0,"—",FLOOR(C9/B9,1)) | E9: =B9*PLANO!B14 | F9: =MAX(0,E9-C9) | G9: =F9*0 | H9: amostra, nao entra no pote de venda
A10: CUSTO DE EMBALAGEM | G10: =SUM(G5:G9)
A12: Custo de embalagem por pote hoje: R$ 1,67 (pote 1,07 + colher 0,26 + lacre 0,34). Com o pote a R$ 0,47 cai para R$ 1,07.

Sheet POTES PRONTOS
A1: ESTOQUE DE PRODUTO ACABADO
A2: Saldo = contagem + entradas - saidas. As entradas e saidas vem da aba MOVIMENTO. Faca uma contagem fisica hoje e corrija a coluna CONTAGEM.
A4: DATA DA CONTAGEM | B4: 22/10/2026 | C4: contagem física — 325 potes
A6: SABOR | B6: CONTAGEM (potes) | C6: ENTRADAS (producao) | D6: SAIDAS (vendas) | E6: SALDO (potes) | F6: PRECO (R$) | G6: VALOR EM ESTOQUE (R$) | H6: RECEITA JA VENDIDA (R$) | I6: OBS
A7: Café Proteico | B7: 40 | C7: =SUMIFS(MOVIMENTO!$D:$D,MOVIMENTO!$C:$C,A7,MOVIMENTO!$B:$B,"PRODUCAO") | D7: =SUMIFS(MOVIMENTO!$D:$D,MOVIMENTO!$C:$C,A7,MOVIMENTO!$B:$B,"VENDA") | E7: =B7+C7-D7 | F7: =PLANO!D7 | G7: =E7*F7 | H7: =D7*F7
A8: Pistache | B8: 46 | C8: =SUMIFS(MOVIMENTO!$D:$D,MOVIMENTO!$C:$C,A8,MOVIMENTO!$B:$B,"PRODUCAO") | D8: =SUMIFS(MOVIMENTO!$D:$D,MOVIMENTO!$C:$C,A8,MOVIMENTO!$B:$B,"VENDA") | E8: =B8+C8-D8 | F8: =PLANO!D8 | G8: =E8*F8 | H8: =D8*F8
A9: Manga com Maracujá | B9: 60 | C9: =SUMIFS(MOVIMENTO!$D:$D,MOVIMENTO!$C:$C,A9,MOVIMENTO!$B:$B,"PRODUCAO") | D9: =SUMIFS(MOVIMENTO!$D:$D,MOVIMENTO!$C:$C,A9,MOVIMENTO!$B:$B,"VENDA") | E9: =B9+C9-D9 | F9: =PLANO!D9 | G9: =E9*F9 | H9: =D9*F9
A10: Sorbet Morango | B10: 32 | C10: =SUMIFS(MOVIMENTO!$D:$D,MOVIMENTO!$C:$C,A10,MOVIMENTO!$B:$B,"PRODUCAO") | D10: =SUMIFS(MOVIMENTO!$D:$D,MOVIMENTO!$C:$C,A10,MOVIMENTO!$B:$B,"VENDA") | E10: =B10+C10-D10 | F10: =PLANO!D10 | G10: =E10*F10 | H10: =D10*F10 | I10: caiu de 53 (13/10) para 32 — ver nota abaixo
A11: Torta de Limão | B11: 58 | C11: =SUMIFS(MOVIMENTO!$D:$D,MOVIMENTO!$C:$C,A11,MOVIMENTO!$B:$B,"PRODUCAO") | D11: =SUMIFS(MOVIMENTO!$D:$D,MOVIMENTO!$C:$C,A11,MOVIMENTO!$B:$B,"VENDA") | E11: =B11+C11-D11 | F11: =PLANO!D11 | G11: =E11*F11 | H11: =D11*F11
A12: Alfajor | B12: 38 | C12: =SUMIFS(MOVIMENTO!$D:$D,MOVIMENTO!$C:$C,A12,MOVIMENTO!$B:$B,"PRODUCAO") | D12: =SUMIFS(MOVIMENTO!$D:$D,MOVIMENTO!$C:$C,A12,MOVIMENTO!$B:$B,"VENDA") | E12: =B12+C12-D12 | F12: =PLANO!D12 | G12: =E12*F12 | H12: =D12*F12 | I12: 0 em 13/10, 38 agora — foi produzido no meio
A13: Brigadeiro Proteico | B13: 51 | C13: =SUMIFS(MOVIMENTO!$D:$D,MOVIMENTO!$C:$C,A13,MOVIMENTO!$B:$B,"PRODUCAO") | D13: =SUMIFS(MOVIMENTO!$D:$D,MOVIMENTO!$C:$C,A13,MOVIMENTO!$B:$B,"VENDA") | E13: =B13+C13-D13 | F13: =PLANO!D13 | G13: =E13*F13 | H13: =D13*F13
A14: TOTAL | B14: =SUM(B7:B13) | C14: =SUM(C7:C13) | D14: =SUM(D7:D13) | E14: =SUM(E7:E13) | G14: =SUM(G7:G13) | H14: =SUM(H7:H13)
A16: A contagem de 22/10 zera a conta: ela e posterior ao pedido 000007, entao os 125 potes daquele pedido JA ESTAO fora deste numero. Por isso as linhas do 000007 na aba MOVIMENTO estao com tipo HISTORICO — ficam visiveis mas nao sao descontadas de novo. Toda contagem fisica nova funciona assim: o que veio antes dela passa a ser historico.
A17: ENTRE 13/10 E 22/10 A PRODUCAO IMPLICITA FOI DE 188 POTES: 262 contados em 13/10, menos 125 vendidos no 000007, daria 137 — e ha 325. Nada dessa producao foi lancada em lugar nenhum.
A18: O MORANGO NAO FECHA. Eram 53 em 13/10 e sairam 15 no pedido 000007, o que deixaria 38 mesmo sem produzir nada. Ha 32. Faltam 6 potes, e as explicacoes possiveis sao degustacao, amostra, perda ou venda nao registrada. Nao da para saber qual — e por isso que o controle de saida precisa comecar.

Sheet TESTES
A1: TESTES DE BANCADA E VERBA MENSAL
A2: Reconstruido das nossas conversas — o sistema nunca registrou lote de teste. Confira a coluna EVIDENCIA antes de confiar na linha.
A4: DATA | B4: MES | C4: TESTE | D4: POR QUE | E4: CALDA (kg) | F4: R$/kg | G4: CUSTO DA CALDA | H4: POTES ENVASADOS | I4: CUSTO EMBALAGEM | J4: CUSTO TOTAL | K4: RESULTADO | L4: DESTINO | M4: EVIDENCIA
C5: Sorbet Melagrana (romã) · oficial | D5: Sabor novo com a pasta MEC3 de romã | E5: 1 | G5: =IF(OR(E5="",F5=""),"",E5*F5) | I5: =IF(H5="","",H5*1.67) | J5: =N(G5)+N(I5) | K5: REPROVADO | L5: descarte | M5: lista do Gabriel, 22/10/2026 — "ficou bem ruim o sabor"; receita não cadastrada
C6: Melagrana · ajuste / reprocesso base leite | D6: Salvar a calda reprovada | G6: =IF(OR(E6="",F6=""),"",E6*F6) | I6: =IF(H6="","",H6*1.67) | J6: =N(G6)+N(I6) | K6: PENDENTE | L6: consumo próprio | M6: lista do Gabriel, 22/10/2026 — pediu o reprocesso para base leite
C7: Sorbet de Cajú | D7: Sabor novo da linha Fresh | G7: =IF(OR(E7="",F7=""),"",E7*F7) | I7: =IF(H7="","",H7*1.67) | J7: =N(G7)+N(I7) | K7: PENDENTE | L7: consumo próprio | M7: lista do Gabriel, 22/10/2026 — receita não cadastrada
C8: Sorbet de Goiaba | D8: Sabor novo da linha Fresh | G8: =IF(OR(E8="",F8=""),"",E8*F8) | I8: =IF(H8="","",H8*1.67) | J8: =N(G8)+N(I8) | K8: PENDENTE | L8: consumo próprio | M8: lista do Gabriel, 22/10/2026 — GOIABA está sem preço no sistema
C9: Sorbet de Siriguela | D9: Sabor novo da linha Fresh | G9: =IF(OR(E9="",F9=""),"",E9*F9) | I9: =IF(H9="","",H9*1.67) | J9: =N(G9)+N(I9) | K9: PENDENTE | L9: consumo próprio | M9: lista do Gabriel, 22/10/2026 — SIRIGUELA (polpa) está sem preço
C10: Avelã com açúcar de maçã | D10: Exercício da apostila do Lulo | G10: =IF(OR(E10="",F10=""),"",E10*F10) | I10: =IF(H10="","",H10*1.67) | J10: =N(G10)+N(I10) | K10: PENDENTE | L10: consumo próprio | M10: lista do Gabriel, 22/10/2026 — PASTA DE AVELA 100% está sem preço; o Gianduia do Lulo (R$ 6,94/kg) é o mais próximo cadastrado
C11: Baunilha tradicional | D11: Par de prova da baunilha proteica | F11: 26.42 | G11: =IF(OR(E11="",F11=""),"",E11*F11) | I11: =IF(H11="","",H11*1.67) | J11: =N(G11)+N(I11) | K11: PENDENTE | L11: consumo próprio | M11: lista do Gabriel, 22/10/2026 — cadastrada como Baunilha · SPECIAL
C12: Baunilha proteica | D12: Linha Boost — o pedido era 15 g de proteína | F12: 47.85 | G12: =IF(OR(E12="",F12=""),"",E12*F12) | I12: =IF(H12="","",H12*1.67) | J12: =N(G12)+N(I12) | K12: PENDENTE | L12: consumo próprio | M12: lista do Gabriel, 22/10/2026 — cadastrada como Baunilha Proteica · BOOST (entrega 13 g, não 15)
C13: Biscoito | D13: Sabor novo com a pasta Biscottino | G13: =IF(OR(E13="",F13=""),"",E13*F13) | I13: =IF(H13="","",H13*1.67) | J13: =N(G13)+N(I13) | K13: PENDENTE | L13: consumo próprio | M13: lista do Gabriel, 22/10/2026 — receita não cadastrada; a pasta tem preço (R$ 192,34/kg)
C14: Yogurt | D14: Sabor novo de base iogurte | F14: 7.2 | G14: =IF(OR(E14="",F14=""),"",E14*F14) | I14: =IF(H14="","",H14*1.67) | J14: =N(G14)+N(I14) | K14: PENDENTE | L14: consumo próprio | M14: lista do Gabriel, 22/10/2026 — custo do Lulo · Iogurte (redução polióis); IOGURTE INTEGRAL está sem preço
C15: Pipoca | D15: Sabor novo com a pasta Gusto Pop-Corn | G15: =IF(OR(E15="",F15=""),"",E15*F15) | I15: =IF(H15="","",H15*1.67) | J15: =N(G15)+N(I15) | K15: PENDENTE | L15: consumo próprio | M15: lista do Gabriel, 22/10/2026 — PASTA GUSTO POP-CORN MEC3 está sem preço, o custo não fecha
C16: Latíssimo | D16: Sabor novo de base leite | F16: 23.04 | G16: =IF(OR(E16="",F16=""),"",E16*F16) | I16: =IF(H16="","",H16*1.67) | J16: =N(G16)+N(I16) | K16: REPROVADO | L16: consumo próprio | M16: lista do Gabriel, 22/10/2026 — "estava ruim"; custo do Fior di Latte ZL como referência
C17: Latíssimo · ajuste da receita | D17: Corrigir o Latíssimo que saiu ruim | F17: 23.04 | G17: =IF(OR(E17="",F17=""),"",E17*F17) | I17: =IF(H17="","",H17*1.67) | J17: =N(G17)+N(I17) | K17: PENDENTE | L17: consumo próprio | M17: lista do Gabriel, 22/10/2026
A18: 24/09/2026 | B18: set/2026 | C18: Torta de Limão · v3 LULO | D18: Subir os parâmetros para a faixa do Lulo | F18: 44.6 | G18: =IF(OR(E18="",F18=""),"",E18*F18) | I18: =IF(H18="","",H18*1.67) | J18: =N(G18)+N(I18) | K18: APROVADO | L18: virou venda | M18: aprovou em bancada: "ficou sensacional"
A19: 24/09/2026 | B19: set/2026 | C19: Brigadeiro Proteico · versão que não pegava ponto | D19: Linha Boost com 12 g de proteína | F19: 56.19 | G19: =IF(OR(E19="",F19=""),"",E19*F19) | I19: =IF(H19="","",H19*1.67) | J19: =N(G19)+N(I19) | K19: REPROVADO | L19: descarte | M19: não pegava ponto — substituída pelo chocolate proteico
A20: 24/09/2026 | B20: set/2026 | C20: Chocolate Proteico (virou o Brigadeiro oficial) | D20: Substituir a versão que não pegava ponto | F20: 41.09 | G20: =IF(OR(E20="",F20=""),"",E20*F20) | I20: =IF(H20="","",H20*1.67) | J20: =N(G20)+N(I20) | K20: APROVADO | L20: virou venda | M20: aprovado no mesmo dia, tomou o nome Brigadeiro
B21: set/2026 | C21: Gelato de Ninho · mix antigo + creme 17% | D21: Validar a textura do mix antigo | G21: =IF(OR(E21="",F21=""),"",E21*F21) | I21: =IF(H21="","",H21*1.67) | J21: =N(G21)+N(I21) | K21: APROVADO | L21: consumo próprio | M21: aprovou a textura: "ficou muito boa"
B22: set/2026 | C22: Mix com inulina | D22: Comparar o mix com e sem inulina | G22: =IF(OR(E22="",F22=""),"",E22*F22) | I22: =IF(H22="","",H22*1.67) | J22: =N(G22)+N(I22) | K22: APROVADO | L22: consumo próprio | M22: "com a inulina no mix tirou o melhor resultado de bancada"
B23: out/2026 | C23: Café Proteico · v6 CREMOBENE | D23: Fornecedor do núcleo Arkeo parou de fornecer | F23: 54.03 | G23: =IF(OR(E23="",F23=""),"",E23*F23) | I23: =IF(H23="","",H23*1.67) | J23: =N(G23)+N(I23) | K23: APROVADO | L23: virou venda | M23: Cremobene entrou em uso oficial depois deste teste
B24: out/2026 | C24: Sorbet Morango · CREMOBENE | D24: Mesma troca de estabilizante | F24: 21.47 | G24: =IF(OR(E24="",F24=""),"",E24*F24) | I24: =IF(H24="","",H24*1.67) | J24: =N(G24)+N(I24) | K24: APROVADO | L24: virou venda | M24: idem
B25: out/2026 | C25: Manga com Maracujá · CREMOBENE | D25: Mesma troca de estabilizante | F25: 26.25 | G25: =IF(OR(E25="",F25=""),"",E25*F25) | I25: =IF(H25="","",H25*1.67) | J25: =N(G25)+N(I25) | K25: APROVADO | L25: virou venda | M25: idem
B26: out/2026 | C26: Alfajor · estévia 0,45 | D26: Primeiro sabor novo pós-lançamento | F26: 33.75 | G26: =IF(OR(E26="",F26=""),"",E26*F26) | I26: =IF(H26="","",H26*1.67) | J26: =N(G26)+N(I26) | K26: APROVADO | L26: virou venda | M26: "receita validada e funcional" — 20 potes no pedido 000007
B27: out/2026 | C27: Pistache · 2 pastas novas, meia a meia | D27: Comparar duas pastas de pistache novas | E27: 1.5 | F27: 22.03 | G27: =IF(OR(E27="",F27=""),"",E27*F27) | I27: =IF(H27="","",H27*1.67) | J27: =N(G27)+N(I27) | K27: PENDENTE | L27: consumo próprio | M27: "vou fazer 1.5kg de pistache pra saborizar metade metade"
B28: out/2026 | C28: Pistache · base neutra para dose de pasta | D28: Achar a dose certa da pasta nova | E28: 0.75 | F28: 22.03 | G28: =IF(OR(E28="",F28=""),"",E28*F28) | I28: =IF(H28="","",H28*1.67) | J28: =N(G28)+N(I28) | K28: PENDENTE | L28: consumo próprio | M28: pediu a dose de pasta para 750 g de base
A29: 22/10/2026 | B29: out/2026 | C29: Canela · pasta PreGel ST-58472 | D29: Sabor novo, pasta recém-chegada | E29: 1 | F29: 24.83 | G29: =IF(OR(E29="",F29=""),"",E29*F29) | I29: =IF(H29="","",H29*1.67) | J29: =N(G29)+N(I29) | K29: PENDENTE | L29: consumo próprio | M29: balanceado em 22/10 — não serve para venda (1,5 g de açúcar adicionado)
C30: Alfajor · estévia 0,30 | D30: Baixar a estévia de 0,45 para 0,30 | F30: 33.75 | G30: =IF(OR(E30="",F30=""),"",E30*F30) | I30: =IF(H30="","",H30*1.67) | J30: =N(G30)+N(I30) | K30: A FAZER | L30: — | M30: pendência aberta desde o cadastro do alfajor
G31: =IF(OR(E31="",F31=""),"",E31*F31) | I31: =IF(H31="","",H31*1.67) | J31: =N(G31)+N(I31)
G32: =IF(OR(E32="",F32=""),"",E32*F32) | I32: =IF(H32="","",H32*1.67) | J32: =N(G32)+N(I32)
G33: =IF(OR(E33="",F33=""),"",E33*F33) | I33: =IF(H33="","",H33*1.67) | J33: =N(G33)+N(I33)
G34: =IF(OR(E34="",F34=""),"",E34*F34) | I34: =IF(H34="","",H34*1.67) | J34: =N(G34)+N(I34)
G35: =IF(OR(E35="",F35=""),"",E35*F35) | I35: =IF(H35="","",H35*1.67) | J35: =N(G35)+N(I35)
G36: =IF(OR(E36="",F36=""),"",E36*F36) | I36: =IF(H36="","",H36*1.67) | J36: =N(G36)+N(I36)
G37: =IF(OR(E37="",F37=""),"",E37*F37) | I37: =IF(H37="","",H37*1.67) | J37: =N(G37)+N(I37)
G38: =IF(OR(E38="",F38=""),"",E38*F38) | I38: =IF(H38="","",H38*1.67) | J38: =N(G38)+N(I38)
G39: =IF(OR(E39="",F39=""),"",E39*F39) | I39: =IF(H39="","",H39*1.67) | J39: =N(G39)+N(I39)
G40: =IF(OR(E40="",F40=""),"",E40*F40) | I40: =IF(H40="","",H40*1.67) | J40: =N(G40)+N(I40)
G41: =IF(OR(E41="",F41=""),"",E41*F41) | I41: =IF(H41="","",H41*1.67) | J41: =N(G41)+N(I41)
...

Sheet MOVIMENTO
A1: MOVIMENTO DE POTES PRONTOS
A2: Uma linha por producao e uma linha por venda, com data a partir de 22/10/2026. Esta aba alimenta POTES PRONTOS automaticamente.
A4: DATA | B4: TIPO | C4: SABOR | D4: POTES | E4: CLIENTE / PEDIDO | F4: OBS
A5: 16/10/2026 | B5: HISTORICO | C5: Brigadeiro Proteico | D5: 20 | E5: Pedido 000007 — O BECO | F5: anterior à contagem de 22/10 — não entra no saldo
A6: 16/10/2026 | B6: HISTORICO | C6: Café Proteico | D6: 15 | E6: Pedido 000007 — O BECO | F6: anterior à contagem de 22/10 — não entra no saldo
A7: 16/10/2026 | B7: HISTORICO | C7: Manga com Maracujá | D7: 15 | E7: Pedido 000007 — O BECO | F7: anterior à contagem de 22/10 — não entra no saldo
A8: 16/10/2026 | B8: HISTORICO | C8: Pistache | D8: 20 | E8: Pedido 000007 — O BECO | F8: anterior à contagem de 22/10 — não entra no saldo
A9: 16/10/2026 | B9: HISTORICO | C9: Torta de Limão | D9: 20 | E9: Pedido 000007 — O BECO | F9: anterior à contagem de 22/10 — não entra no saldo
A10: 16/10/2026 | B10: HISTORICO | C10: Sorbet Morango | D10: 15 | E10: Pedido 000007 — O BECO | F10: anterior à contagem de 22/10 — não entra no saldo
A11: 16/10/2026 | B11: HISTORICO | C11: Alfajor | D11: 20 | E11: Pedido 000007 — O BECO | F11: anterior à contagem de 22/10 — não entra no saldo
